Workbook

Sheet Oct 2023
A1: PAYLOAD REPORT BY ROUTE AND MONTH OCT 2023
C2: Aversen | F2: Aversen | I2: Aversen | L2: Jerome | O2: Jerome | R2: Aversen | U2: Ansar | X2: Ansar | AA2: Ansar | AD2: Ansar | AG2: Ansar | AJ2: Brent | AM2: Brent | AP2: Brent | AS2: Brent | AV2: Brent | AY2: Sune | BB2: Sune | BE2: Sune | BH2: Sune | BJ2: Total vehicles
B3: Route Kzn - Western Cape | E3: Route Kzn - Northern Cape | H3: Route Kzn - Gauteng | K3: Route Kzn - Kzn Dealer | N3: Route DCT - VDC / Other S/Yard | Q3: Route Kzn - Other | T3: Route Western Cape to PE | W3: Route Western Cape to EL | Z3: Route Western Cape to Kzn | AC3: Route Western Cape to GP | AF3: Route Western Cape to Other | AI3: Route PE - Kzn | AL3: Route PE - Western Cape | AO3: Route PE - Gauteng | AR3: Route PE - Freestate | AU3: Route PE - Other | AX3: Route Gauteng - Kzn | BA3: Route Gauteng - Eastern Cape | BD3: Route Gauteng - Western Cape | BG3: Route Gauteng - Other | BJ3: TOTALS
A4: DAY DATE | B4: Total vehicles | C4: Total Carriers | D4: Payload | E4: Total vehicles | F4: Total Carriers | G4: Payload | H4: Total vehicles | I4: Total Carriers | J4: Payload | K4: Total vehicles | L4: Total Carriers | M4: Payload | N4: Total vehicles | O4: Total Carriers | P4: Payload | Q4: Total vehicles | R4: Total Carriers | S4: Payload | T4: Total vehicles | U4: Total Carriers | V4: Payload | W4: Total vehicles | X4: Total Carriers | Y4: Payload | Z4: Total vehicles | AA4: Total Carriers | AB4: Payload | AC4: Total vehicles | AD4: Total Carriers | AE4: Payload | AF4: Total vehicles | AG4: Total Carriers | AH4: Payload | AI4: Total vehicles | AJ4: Total Carriers | AK4: Payload | AL4: Total vehicles | AM4: Total Carriers | AN4: Payload | AO4: Total vehicles | AP4: Total Carriers | AQ4: Payload | AR4: Total vehicles | AS4: Total Carriers | AT4: Payload | AU4: Total vehicles | AV4: Total Carriers | AW4: Payload | AX4: Total vehicles | AY4: Total Carriers | AZ4: Payload | BA4: Total vehicles | BB4: Total Carriers | BC4: Payload | BD4: Total vehicles | BE4: Total Carriers | BF4: Payload | BG4: Total vehicles | BH4: Total Carriers | BI4: Payload | BJ4: Total vehicles | BK4: Total Carriers | BL4: Payload
A5: 45200 | B5: 36 | C5: 4 | D5: =IF(C5=0,"",B5/C5) -> 9 | E5: 8 | F5: 1 | G5: =IF(F5=0,"",E5/F5) -> 8 | H5: 0 | I5: 0 | J5: 0 | K5: 17 | L5: 3 | M5: =IF(L5=0,"",K5/L5) -> 5.6666667 | N5: 232 | O5: 36 | P5: =IF(O5=0,"",N5/O5) -> 6.4444444 | Q5: 0 | R5: 0 | S5: =IF(R5=0,"",Q5/R5) | T5: 0 | U5: 0 | V5: =IF(U5=0,"",T5/U5) | W5: 0 | X5: 0 | Y5: 0 | Z5: 0 | AA5: 0 | AB5: 0 | AC5: 0 | AD5: 0 | AE5: 0 | AF5: 0 | AG5: 0 | AH5: 0 | AI5: 26 | AJ5: 4 | AK5: =IF(AJ5=0,"",AI5/AJ5) -> 6.5 | AL5: 0 | AM5: 0 | AN5: 0 | AO5: 0 | AP5: 0 | AQ5: 0 | AR5: 0 | AS5: 0 | AT5: 0 | AU5: 0 | AV5: 0 | AW5: 0 | AX5: 7 | AY5: 1 | AZ5: =IF(AY5=0,"",AX5/AY5) -> 7 | BA5: 0 | BB5: 0 | BC5: 0 | BD5: 0 | BE5: 0 | BF5: 0 | BG5: 0 | BH5: 0 | BI5: 0 | BJ5: =BG5+BD5+BA5+AX5+AU5+AR5+AO5+AL5+AI5+Q5+N5+K5+H5+E5+AF5+AC5+Z5+W5+T5+B5 -> 326 | BK5: =BH5+BE5+BB5+AY5+AV5+AS5+AP5+AM5+AJ5+R5+O5+L5+I5+F5+AG5+AD5+AA5+X5+U5+C5 -> 49 | BL5: =IF(BK5=0,"",BJ5/BK5) -> 6.6530612
A6: 45201 | B6: 45 | C6: 5 | D6: =IF(C6=0,"",B6/C6) -> 9 | E6: 0 | F6: 0 | G6: - | H6: 0 | I6: 0 | J6: 0 | K6: 31 | L6: 5 | M6: =IF(L6=0,"",K6/L6) -> 6.2 | N6: 370 | O6: 60 | P6: =IF(O6=0,"",N6/O6) -> 6.1666667 | Q6: 0 | R6: 0 | S6: =IF(R6=0,"",Q6/R6) | T6: 5 | U6: 1 | V6: =IF(U6=0,"",T6/U6) -> 5 | W6: 0 | X6: 0 | Y6: 0 | Z6: 0 | AA6: 0 | AB6: 0 | AC6: 0 | AD6: 0 | AE6: 0 | AF6: 1 | AG6: 1 | AH6: 0 | AI6: 19 | AJ6: 3 | AK6: =IF(AJ6=0,"",AI6/AJ6) -> 6.3333333 | AL6: 0 | AM6: 0 | AN6: 0 | AO6: 0 | AP6: 0 | AQ6: 0 | AR6: 0 | AS6: 0 | AT6: 0 | AU6: 0 | AV6: 0 | AW6: 0 | AX6: 0 | AY6: 0 | AZ6: 0 | BA6: 0 | BB6: 0 | BC6: 0 | BD6: 0 | BE6: 0 | BF6: 0 | BG6: 0 | BH6: 0 | BI6: 0 | BJ6: =BG6+BD6+BA6+AX6+AU6+AR6+AO6+AL6+AI6+Q6+N6+K6+H6+E6+AF6+AC6+Z6+W6+T6+B6 -> 471 | BK6: =BH6+BE6+BB6+AY6+AV6+AS6+AP6+AM6+AJ6+R6+O6+L6+I6+F6+AG6+AD6+AA6+X6+U6+C6 -> 75 | BL6: =IF(BK6=0,"",BJ6/BK6) -> 6.28
A7: 45202 | B7: 93 | C7: 11 | D7: =IF(C7=0,"",B7/C7) -> 8.4545455 | E7: 8 | F7: 1 | G7: =IF(F7=0,"",E7/F7) -> 8 | H7: 0 | I7: 0 | J7: 0 | K7: 46 | L7: 8 | M7: =IF(L7=0,"",K7/L7) -> 5.75 | N7: 297 | O7: 50 | P7: =IF(O7=0,"",N7/O7) -> 5.94 | Q7: 0 | R7: 0 | S7: =IF(R7=0,"",Q7/R7) | T7: 1 | U7: 1 | V7: =IF(U7=0,"",T7/U7) -> 1 | W7: 0 | X7: 0 | Y7: 0 | Z7: 0 | AA7: 0 | AB7: 0 | AC7: 0 | AD7: 0 | AE7: 0 | AF7: 0 | AG7: 0 | AH7: 0 | AI7: 13 | AJ7: 2 | AK7: =IF(AJ7=0,"",AI7/AJ7) -> 6.5 | AL7: 0 | AM7: 0 | AN7: 0 | AO7: 0 | AP7: 0 | AQ7: 0 | AR7: 0 | AS7: 0 | AT7: 0 | AU7: 0 | AV7: 0 | AW7: 0 | AX7: 0 | AY7: 0 | AZ7: 0 | BA7: 0 | BB7: 0 | BC7: 0 | BD7: 0 | BE7: 0 | BF7: 0 | BG7: 0 | BH7: 0 | BI7: 0 | BJ7: =BG7+BD7+BA7+AX7+AU7+AR7+AO7+AL7+AI7+Q7+N7+K7+H7+E7+AF7+AC7+Z7+W7+T7+B7 -> 458 | BK7: =BH7+BE7+BB7+AY7+AV7+AS7+AP7+AM7+AJ7+R7+O7+L7+I7+F7+AG7+AD7+AA7+X7+U7+C7 -> 73 | BL7: =IF(BK7=0,"",BJ7/BK7) -> 6.2739726
A8: 45203 | B8: 61 | C8: 7 | D8: =IF(C8=0,"",B8/C8) -> 8.7142857 | E8: 8 | F8: 1 | G8: =IF(F8=0,"",E8/F8) -> 8 | H8: 18 | I8: 2 | J8: =IF(I8=0,"",H8/I8) -> 9 | K8: 69 | L8: 14 | M8: =IF(L8=0,"",K8/L8) -> 4.9285714 | N8: 25 | O8: 4 | P8: =IF(O8=0,"",N8/O8) -> 6.25 | Q8: 0 | R8: 0 | S8: =IF(R8=0,"",Q8/R8) | T8: 3 | U8: 1 | V8: =IF(U8=0,"",T8/U8) -> 3 | W8: 0 | X8: 0 | Y8: 0 | Z8: 0 | AA8: 0 | AB8: 0 | AC8: 0 | AD8: 0 | AE8: 0 | AF8: 0 | AG8: 0 | AH8: 0 | AI8: 30 | AJ8: 4 | AK8: =IF(AJ8=0,"",AI8/AJ8) -> 7.5 | AL8: 0 | AM8: 0 | AN8: 0 | AO8: 0 | AP8: 0 | AQ8: 0 | AR8: 0 | AS8: 0 | AT8: 0 | AU8: 0 | AV8: 0 | AW8: 0 | AX8: 0 | AY8: 0 | AZ8: 0 | BA8: 0 | BB8: 0 | BC8: 0 | BD8: 0 | BE8: 0 | BF8: 0 | BG8: 0 | BH8: 0 | BI8: 0 | BJ8: =BG8+BD8+BA8+AX8+AU8+AR8+AO8+AL8+AI8+Q8+N8+K8+H8+E8+AF8+AC8+Z8+W8+T8+B8 -> 214 | BK8: =BH8+BE8+BB8+AY8+AV8+AS8+AP8+AM8+AJ8+R8+O8+L8+I8+F8+AG8+AD8+AA8+X8+U8+C8 -> 33 | BL8: =IF(BK8=0,"",BJ8/BK8) -> 6.4848485
A9: 45204 | B9: 58 | C9: 6 | D9: =IF(C9=0,"",B9/C9) -> 9.6666667 | E9: 5 | F9: 1 | G9: =IF(F9=0,"",E9/F9) -> 5 | H9: 21 | I9: 3 | J9: =IF(I9=0,"",H9/I9) -> 7 | K9: 15 | L9: 3 | M9: =IF(L9=0,"",K9/L9) -> 5 | N9: 0 | O9: 0 | P9: =IF(O9=0,"",N9/O9) | Q9: 16 | R9: 2 | S9: =IF(R9=0,"",Q9/R9) -> 8 | T9: 0 | U9: 0 | V9: =IF(U9=0,"",T9/U9) | W9: 0 | X9: 0 | Y9: 0 | Z9: 0 | AA9: 0 | AB9: 0 | AC9: 0 | AD9: 0 | AE9: 0 | AF9: 0 | AG9: 0 | AH9: 0 | AI9: 26 | AJ9: 3 | AK9: =IF(AJ9=0,"",AI9/AJ9) -> 8.6666667 | AL9: 0 | AM9: 0 | AN9: 0 | AO9: 0 | AP9: 0 | AQ9: 0 | AR9: 0 | AS9: 0 | AT9: 0 | AU9: 0 | AV9: 0 | AW9: 0 | AX9: 8 | AY9: 1 | AZ9: =IF(AY9=0,"",AX9/AY9) -> 8 | BA9: 0 | BB9: 0 | BC9: 0 | BD9: 0 | BE9: 0 | BF9: 0 | BG9: 0 | BH9: 0 | BI9: 0 | BJ9: =BG9+BD9+BA9+AX9+AU9+AR9+AO9+AL9+AI9+Q9+N9+K9+H9+E9+AF9+AC9+Z9+W9+T9+B9 -> 149 | BK9: =BH9+BE9+BB9+AY9+AV9+AS9+AP9+AM9+AJ9+R9+O9+L9+I9+F9+AG9+AD9+AA9+X9+U9+C9 -> 19 | BL9: =IF(BK9=0,"",BJ9/BK9) -> 7.8421053
A10: 45205 | B10: 53 | C10: 6 | D10: =IF(C10=0,"",B10/C10) -> 8.8333333 | E10: 18 | F10: 3 | G10: =IF(F10=0,"",E10/F10) -> 6 | H10: 0 | I10: 0 | J10: 0 | K10: 24 | L10: 5 | M10: =IF(L10=0,"",K10/L10) -> 4.8 | N10: 0 | O10: 0 | P10: =IF(O10=0,"",N10/O10) | Q10: 0 | R10: 0 | S10: =IF(R10=0,"",Q10/R10) | T10: 6 | U10: 2 | V10: =IF(U10=0,"",T10/U10) -> 3 | W10: 0 | X10: 0 | Y10: 0 | Z10: 0 | AA10: 0 | AB10: 0 | AC10: 0 | AD10: 0 | AE10: 0 | AF10: 0 | AG10: 0 | AH10: 0 | AI10: 26 | AJ10: 3 | AK10: =IF(AJ10=0,"",AI10/AJ10) -> 8.6666667 | AL10: 0 | AM10: 0 | AN10: 0 | AO10: 0 | AP10: 0 | AQ10: 0 | AR10: 0 | AS10: 0 | AT10: 0 | AU10: 0 | AV10: 0 | AW10: 0 | AX10: 18 | AY10: 3 | AZ10: =IF(AY10=0,"",AX10/AY10) -> 6 | BA10: 0 | BB10: 0 | BC10: 0 | BD10: 0 | BE10: 0 | BF10: 0 | BG10: 1 | BH10: 1 | BI10: =IF(BH10=0,"",BG10/BH10) -> 1 | BJ10: =BG10+BD10+BA10+AX10+AU10+AR10+AO10+AL10+AI10+Q10+N10+K10+H10+E10+AF10+AC10+Z10+W10+T10+B10 -> 146 | BK10: =BH10+BE10+BB10+AY10+AV10+AS10+AP10+AM10+AJ10+R10+O10+L10+I10+F10+AG10+AD10+AA10+X10+U10+C10 -> 23 | BL10: =IF(BK10=0,"",BJ10/BK10) -> 6.3478261
A11: 45206 | B11: 129 | C11: 16 | D11: =IF(C11=0,"",B11/C11) -> 8.0625 | E11: 0 | F11: 0 | G11: 0 | H11: 0 | I11: 0 | J11: 0 | K11: 0 | L11: 0 | M11: 0 | N11: 0 | O11: 0 | P11: =IF(O11=0,"",N11/O11) | Q11: 0 | R11: 0 | S11: =IF(R11=0,"",Q11/R11) | T11: 0 | U11: 0 | V11: =IF(U11=0,"",T11/U11) | W11: 0 | X11: 0 | Y11: 0 | Z11: 0 | AA11: 0 | AB11: 0 | AC11: 0 | AD11: 0 | AE11: 0 | AF11: 0 | AG11: 0 | AH11: 0 | AI11: 8 | AJ11: 1 | AK11: =IF(AJ11=0,"",AI11/AJ11) -> 8 | AL11: 0 | AM11: 0 | AN11: 0 | AO11: 0 | AP11: 0 | AQ11: 0 | AR11: 7 | AS11: 1 | AT11: =IF(AS11=0,"",AR11/AS11) -> 7 | AU11: 0 | AV11: 0 | AW11: 0 | AX11: 0 | AY11: 0 | AZ11: 0 | BA11: 0 | BB11: 0 | BC11: 0 | BD11: 0 | BE11: 0 | BF11: 0 | BG11: 0 | BH11: 0 | BI11: 0 | BJ11: =BG11+BD11+BA11+AX11+AU11+AR11+AO11+AL11+AI11+Q11+N11+K11+H11+E11+AF11+AC11+Z11+W11+T11+B11 -> 144 | BK11: =BH11+BE11+BB11+AY11+AV11+AS11+AP11+AM11+AJ11+R11+O11+L11+I11+F11+AG11+AD11+AA11+X11+U11+C11 -> 18 | BL11: =IF(BK11=0,"",BJ11/BK11) -> 8
A12: 45207 | B12: 40 | C12: 5 | D12: =IF(C12=0,"",B12/C12) -> 8 | E12: 0 | F12: 0 | G12: 0 | H12: 0 | I12: 0 | J12: 0 | K12: 0 | L12: 0 | M12: 0 | N12: 0 | O12: 0 | P12: =IF(O12=0,"",N12/O12) | Q12: 0 | R12: 0 | S12: =IF(R12=0,"",Q12/R12) | T12: 0 | U12: 0 | V12: =IF(U12=0,"",T12/U12) | W12: 0 | X12: 0 | Y12: 0 | Z12: 0 | AA12: 0 | AB12: 0 | AC12: 0 | AD12: 0 | AE12: 0 | AF12: 0 | AG12: 0 | AH12: 0 | AI12: 30 | AJ12: 4 | AK12: =IF(AJ12=0,"",AI12/AJ12) -> 7.5 | AL12: 0 | AM12: 0 | AN12: 0 | AO12: 0 | AP12: 0 | AQ12: 0 | AR12: 0 | AS12: 0 | AT12: 0 | AU12: 0 | AV12: 0 | AW12: 0 | AX12: 8 | AY12: 1 | AZ12: =IF(AY12=0,"",AX12/AY12) -> 8 | BA12: 0 | BB12: 0 | BC12: 0 | BD12: 0 | BE12: 0 | BF12: 0 | BG12: 0 | BH12: 0 | BI12: 0 | BJ12: =BG12+BD12+BA12+AX12+AU12+AR12+AO12+AL12+AI12+Q12+N12+K12+H12+E12+AF12+AC12+Z12+W12+T12+B12 -> 78 | BK12: =BH12+BE12+BB12+AY12+AV12+AS12+AP12+AM12+AJ12+R12+O12+L12+I12+F12+AG12+AD12+AA12+X12+U12+C12 -> 10 | BL12: =IF(BK12=0,"",BJ12/BK12) -> 7.8
A13: 45208 | B13: 16 | C13: 2 | D13: =IF(C13=0,"",B13/C13) -> 8 | E13: 0 | F13: 0 | G13: 0 | H13: 6 | I13: 1 | J13: =IF(I13=0,"",H13/I13) -> 6 | K13: 5 | L13: 1 | M13: =IF(L13=0,"",K13/L13) -> 5 | N13: 329 | O13: 63 | P13: =IF(O13=0,"",N13/O13) -> 5.2222222 | Q13: 19 | R13: 5 | S13: =IF(R13=0,"",Q13/R13) -> 3.8 | T13: 0 | U13: 0 | V13: =IF(U13=0,"",T13/U13) | W13: 0 | X13: 0 | Y13: 0 | Z13: 0 | AA13: 0 | AB13: 0 | AC13: 0 | AD13: 0 | AE13: 0 | AF13: 20 | AG13: 5 | AH13: =IF(AG13=0,"",AF13/AG13) -> 4 | AI13: 8 | AJ13: 1 | AK13: =IF(AJ13=0,"",AI13/AJ13) -> 8 | AL13: 0 | AM13: 0 | AN13: 0 | AO13: 0 | AP13: 0 | AQ13: 0 | AR13: 5 | AS13: 1 | AT13: =IF(AS13=0,"",AR13/AS13) -> 5 | AU13: 0 | AV13: 0 | AW13: 0 | AX13: 0 | AY13: 0 | AZ13: 0 | BA13: 0 | BB13: 0 | BC13: 0 | BD13: 0 | BE13: 0 | BF13: 0 | BG13: 0 | BH13: 0 | BI13: 0 | BJ13: =BG13+BD13+BA13+AX13+AU13+AR13+AO13+AL13+AI13+Q13+N13+K13+H13+E13+AF13+AC13+Z13+W13+T13+B13 -> 408 | BK13: =BH13+BE13+BB13+AY13+AV13+AS13+AP13+AM13+AJ13+R13+O13+L13+I13+F13+AG13+AD13+AA13+X13+U13+C13 -> 79 | BL13: =IF(BK13=0,"",BJ13/BK13) -> 5.164557
A14: 45209 | B14: 29 | C14: 4 | D14: =IF(C14=0,"",B14/C14) -> 7.25 | E14: 7 | F14: 1 | G14: =IF(F14=0,"",E14/F14) -> 7 | H14: 6 | I14: 1 | J14: =IF(I14=0,"",H14/I14) -> 6 | K14: 11 | L14: 2 | M14: =IF(L14=0,"",K14/L14) -> 5.5 | N14: 4 | O14: 1 | P14: =IF(O14=0,"",N14/O14) -> 4 | Q14: 25 | R14: 1 | S14: =IF(R14=0,"",Q14/R14) -> 25 | T14: 8 | U14: 1 | V14: =IF(U14=0,"",T14/U14) -> 8 | W14: 0 | X14: 0 | Y14: 0 | Z14: 0 | AA14: 0 | AB14: 0 | AC14: 0 | AD14: 0 | AE14: 0 | AF14: 3 | AG14: 1 | AH14: =IF(AG14=0,"",AF14/AG14) -> 3 | AI14: 27 | AJ14: 3 | AK14: =IF(AJ14=0,"",AI14/AJ14) -> 9 | AL14: 0 | AM14: 0 | AN14: 0 | AO14: 0 | AP14: 0 | AQ14: 0 | AR14: 0 | AS14: 0 | AT14: 0 | AU14: 0 | AV14: 0 | AW14: 0 | AX14: 5 | AY14: 1 | AZ14: =IF(AY14=0,"",AX14/AY14) -> 5 | BA14: 0 | BB14: 0 | BC14: 0 | BD14: 0 | BE14: 0 | BF14: 0 | BG14: 2 | BH14: 1 | BI14: =IF(BH14=0,"",BG14/BH14) -> 2 | BJ14: =BG14+BD14+BA14+AX14+AU14+AR14+AO14+AL14+AI14+Q14+N14+K14+H14+E14+AF14+AC14+Z14+W14+T14+B14 -> 127 | BK14: =BH14+BE14+BB14+AY14+AV14+AS14+AP14+AM14+AJ14+R14+O14+L14+I14+F14+AG14+AD14+AA14+X14+U14+C14 -> 17 | BL14: =IF(BK14=0,"",BJ14/BK14) -> 7.4705882
A15: 45210 | B15: 19 | C15: 4 | D15: =IF(C15=0,"",B15/C15) -> 4.75 | E15: 0 | F15: 0 | G15: 0 | H15: 36 | I15: 4 | J15: =IF(I15=0,"",H15/I15) -> 9 | K15: 12 | L15: 2 | M15: =IF(L15=0,"",K15/L15) -> 6 | N15: 48 | O15: 10 | P15: =IF(O15=0,"",N15/O15) -> 4.8 | Q15: 37 | R15: 6 | S15: =IF(R15=0,"",Q15/R15) -> 6.1666667 | T15: 0 | U15: 0 | V15: =IF(U15=0,"",T15/U15) | W15: 0 | X15: 0 | Y15: 0 | Z15: 1 | AA15: 1 | AB15: =IF(AA15=0,"",Z15/AA15) -> 1 | AC15: 0 | AD15: 0 | AE15: 0 | AF15: 0 | AG15: 0 | AH15: 0 | AI15: 50 | AJ15: 6 | AK15: =IF(AJ15=0,"",AI15/AJ15) -> 8.3333333 | AL15: 0 | AM15: 0 | AN15: 0 | AO15: 0 | AP15: 0 | AQ15: 0 | AR15: 0 | AS15: 0 | AT15: 0 | AU15: 0 | AV15: 0 | AW15: 0 | AX15: 6 | AY15: 1 | AZ15: =IF(AY15=0,"",AX15/AY15) -> 6 | BA15: 0 | BB15: 0 | BC15: 0 | BD15: 0 | BE15: 0 | BF15: 0 | BG15: 0 | BH15: 0 | BI15: 0 | BJ15: =BG15+BD15+BA15+AX15+AU15+AR15+AO15+AL15+AI15+Q15+N15+K15+H15+E15+AF15+AC15+Z15+W15+T15+B15 -> 209 | BK15: =BH15+BE15+BB15+AY15+AV15+AS15+AP15+AM15+AJ15+R15+O15+L15+I15+F15+AG15+AD15+AA15+X15+U15+C15 -> 34 | BL15: =IF(BK15=0,"",BJ15/BK15) -> 6.1470588
A16: 45211 | B16: 48 | C16: 6 | D16: =IF(C16=0,"",B16/C16) -> 8 | E16: 7 | F16: 1 | G16: =IF(F16=0,"",E16/F16) -> 7 | H16: 0 | I16: 0 | J16: 0 | K16: 29 | L16: 5 | M16: =IF(L16=0,"",K16/L16) -> 5.8 | N16: 0 | O16: 0 | P16: =IF(O16=0,"",N16/O16) | Q16: 0 | R16: 0 | S16: =IF(R16=0,"",Q16/R16) | T16: 8 | U16: 1 | V16: =IF(U16=0,"",T16/U16) -> 8 | W16: 0 | X16: 0 | Y16: 0 | Z16: 0 | AA16: 0 | AB16: 0 | AC16: 0 | AD16: 0 | AE16: 0 | AF16: 0 | AG16: 0 | AH16: 0 | AI16: 36 | AJ16: 4 | AK16: =IF(AJ16=0,"",AI16/AJ16) -> 9 | AL16: 0 | AM16: 0 | AN16: 0 | AO16: 0 | AP16: 0 | AQ16: 0 | AR16: 0 | AS16: 0 | AT16: 0 | AU16: 0 | AV16: 0 | AW16: 0 | AX16: 32 | AY16: 4 | AZ16: =IF(AY16=0,"",AX16/AY16) -> 8 | BA16: 0 | BB16: 0 | BC16: 0 | BD16: 0 | BE16: 0 | BF16: 0 | BG16: 0 | BH16: 0 | BI16: 0 | BJ16: =BG16+BD16+BA16+AX16+AU16+AR16+AO16+AL16+AI16+Q16+N16+K16+H16+E16+AF16+AC16+Z16+W16+T16+B16 -> 160 | BK16: =BH16+BE16+BB16+AY16+AV16+AS16+AP16+AM16+AJ16+R16+O16+L16+I16+F16+AG16+AD16+AA16+X16+U16+C16 -> 21 | BL16: =IF(BK16=0,"",BJ16/BK16) -> 7.6190476
A17: 45212 | B17: 138 | C17: 14 | D17: =IF(C17=0,"",B17/C17) -> 9.8571429 | E17: 0 | F17: 0 | G17: 0 | H17: 9 | I17: 1 | J17: =IF(I17=0,"",H17/I17) -> 9 | K17: 5 | L17: 1 | M17: =IF(L17=0,"",K17/L17) -> 5 | N17: 0 | O17: 0 | P17: =IF(O17=0,"",N17/O17) | Q17: 0 | R17: 0 | S17: =IF(R17=0,"",Q17/R17) | T17: 1 | U17: 1 | V17: =IF(U17=0,"",T17/U17) -> 1 | W17: 0 | X17: 0 | Y17: 0 | Z17: 1 | AA17: 1 | AB17: =IF(AA17=0,"",Z17/AA17) -> 1 | AC17: 0 | AD17: 0 | AE17: 0 | AF17: 0 | AG17: 0 | AH17: 0 | AI17: 42 | AJ17: 5 | AK17: =IF(AJ17=0,"",AI17/AJ17) -> 8.4 | AL17: 0 | AM17: 0 | AN17: 0 | AO17: 0 | AP17: 0 | AQ17: 0 | AR17: 0 | AS17: 0 | AT17: 0 | AU17: 0 | AV17: 0 | AW17: 0 | AX17: 6 | AY17: 1 | AZ17: =IF(AY17=0,"",AX17/AY17) -> 6 | BA17: 0 | BB17: 0 | BC17: 0 | BD17: 0 | BE17: 0 | BF17: 0 | BG17: 0 | BH17: 0 | BI17: 0 | BJ17: =BG17+BD17+BA17+AX17+AU17+AR17+AO17+AL17+AI17+Q17+N17+K17+H17+E17+AF17+AC17+Z17+W17+T17+B17 -> 202 | BK17: =BH17+BE17+BB17+AY17+AV17+AS17+AP17+AM17+AJ17+R17+O17+L17+I17+F17+AG17+AD17+AA17+X17+U17+C17 -> 24 | BL17: =IF(BK17=0,"",BJ17/BK17) -> 8.4166667
A18: 45213 | B18: 63 | C18: 7 | D18: =IF(C18=0,"",B18/C18) -> 9 | E18: 7 | F18: 1 | G18: =IF(F18=0,"",E18/F18) -> 7 | H18: 0 | I18: 0 | J18: 0 | K18: 5 | L18: 1 | M18: =IF(L18=0,"",K18/L18) -> 5 | N18: 0 | O18: 0 | P18: =IF(O18=0,"",N18/O18) | Q18: 9 | R18: 1 | S18: =IF(R18=0,"",Q18/R18) -> 9 | T18: 8 | U18: 2 | V18: =IF(U18=0,"",T18/U18) -> 4 | W18: 0 | X18: 0 | Y18: 0 | Z18: 1 | AA18: 1 | AB18: =IF(AA18=0,"",Z18/AA18) -> 1 | AC18: 0 | AD18: 0 | AE18: 0 | AF18: 0 | AG18: 0 | AH18: 0 | AI18: 9 | AJ18: 1 | AK18: =IF(AJ18=0,"",AI18/AJ18) -> 9 | AL18: 0 | AM18: 0 | AN18: 0 | AO18: 0 | AP18: 0 | AQ18: 0 | AR18: 0 | AS18: 0 | AT18: 0 | AU18: 0 | AV18: 0 | AW18: 0 | AX18: 5 | AY18: 1 | AZ18: =IF(AY18=0,"",AX18/AY18) -> 5 | BA18: 0 | BB18: 0 | BC18: 0 | BD18: 0 | BE18: 0 | BF18: 0 | BG18: 0 | BH18: 0 | BI18: 0 | BJ18: =BG18+BD18+BA18+AX18+AU18+AR18+AO18+AL18+AI18+Q18+N18+K18+H18+E18+AF18+AC18+Z18+W18+T18+B18 -> 107 | BK18: =BH18+BE18+BB18+AY18+AV18+AS18+AP18+AM18+AJ18+R18+O18+L18+I18+F18+AG18+AD18+AA18+X18+U18+C18 -> 15 | BL18: =IF(BK18=0,"",BJ18/BK18) -> 7.1333333
A19: 45214 | B19: 64 | C19: 7 | D19: =IF(C19=0,"",B19/C19) -> 9.1428571 | E19: 0 | F19: 0 | G19: 0 | H19: 17 | I19: 3 | J19: =IF(I19=0,"",H19/I19) -> 5.6666667 | K19: 49 | L19: 7 | M19: =IF(L19=0,"",K19/L19) -> 7 | N19: 123 | O19: 28 | P19: =IF(O19=0,"",N19/O19) -> 4.3928571 | Q19: 0 | R19: 0 | S19: =IF(R19=0,"",Q19/R19) | T19: 0 | U19: 0 | V19: =IF(U19=0,"",T19/U19) | W19: 0 | X19: 0 | Y19: 0 | Z19: 0 | AA19: 0 | AB19: 0 | AC19: 0 | AD19: 0 | AE19: 0 | AF19: 0 | AG19: 0 | AH19: 0 | AI19: 17 | AJ19: 3 | AK19: =IF(AJ19=0,"",AI19/AJ19) -> 5.6666667 | AL19: 0 | AM19: 0 | AN19: 0 | AO19: 0 | AP19: 0 | AQ19: 0 | AR19: 13 | AS19: 2 | AT19: =IF(AS19=0,"",AR19/AS19) -> 6.5 | AU19: 1 | AV19: 1 | AW19: =IF(AV19=0,"",AU19/AV19) -> 1 | AX19: 0 | AY19: 0 | AZ19: 0 | BA19: 0 | BB19: 0 | BC19: 0 | BD19: 0 | BE19: 0 | BF19: 0 | BG19: 0 | BH19: 0 | BI19: 0 | BJ19: =BG19+BD19+BA19+AX19+AU19+AR19+AO19+AL19+AI19+Q19+N19+K19+H19+E19+AF19+AC19+Z19+W19+T19+B19 -> 284 | BK19: =BH19+BE19+BB19+AY19+AV19+AS19+AP19+AM19+AJ19+R19+O19+L19+I19+F19+AG19+AD19+AA19+X19+U19+C19 -> 51 | BL19: =IF(BK19=0,"",BJ19/BK19) -> 5.5686275
A20: 45215 | B20: 25 | C20: 3 | D20: =IF(C20=0,"",B20/C20) -> 8.3333333 | E20: 0 | F20: 0 | G20: 0 | H20: 0 | I20: 0 | J20: 0 | K20: 83 | L20: 13 | M20: =IF(L20=0,"",K20/L20) -> 6.3846154 | N20: 7 | O20: 2 | P20: =IF(O20=0,"",N20/O20) -> 3.5 | Q20: 0 | R20: 0 | S20: =IF(R20=0,"",Q20/R20) | T20: 9 | U20: 1 | V20: =IF(U20=0,"",T20/U20) -> 9 | W20: 0 | X20: 0 | Y20: 0 | Z20: 0 | AA20: 0 | AB20: 0 | AC20: 0 | AD20: 0 | AE20: 0 | AF20: 4 | AG20: 1 | AH20: =IF(AG20=0,"",AF20/AG20) -> 4 | AI20: 9 | AJ20: 1 | AK20: =IF(AJ20=0,"",AI20/AJ20) -> 9 | AL20: 0 | AM20: 0 | AN20: 0 | AO20: 0 | AP20: 0 | AQ20: 0 | AR20: 0 | AS20: 0 | AT20: 0 | AU20: 0 | AV20: 0 | AW20: 0 | AX20: 10 | AY20: 2 | AZ20: =IF(AY20=0,"",AX20/AY20) -> 5 | BA20: 0 | BB20: 0 | BC20: 0 | BD20: 0 | BE20: 0 | BF20: 0 | BG20: 0 | BH20: 0 | BI20: 0 | BJ20: =BG20+BD20+BA20+AX20+AU20+AR20+AO20+AL20+AI20+Q20+N20+K20+H20+E20+AF20+AC20+Z20+W20+T20+B20 -> 147 | BK20: =BH20+BE20+BB20+AY20+AV20+AS20+AP20+AM20+AJ20+R20+O20+L20+I20+F20+AG20+AD20+AA20+X20+U20+C20 -> 23 | BL20: =IF(BK20=0,"",BJ20/BK20) -> 6.3913043
A21: 45216 | B21: 88 | C21: 12 | D21: =IF(C21=0,"",B21/C21) -> 7.3333333 | E21: 12 | F21: 2 | G21: =IF(F21=0,"",E21/F21) -> 6 | H21: 0 | I21: 0 | J21: 0 | K21: 31 | L21: 5 | M21: =IF(L21=0,"",K21/L21) -> 6.2 | N21: 231 | O21: 37 | P21: =IF(O21=0,"",N21/O21) -> 6.2432432 | Q21: 0 | R21: 0 | S21: =IF(R21=0,"",Q21/R21) | T21: 0 | U21: 0 | V21: =IF(U21=0,"",T21/U21) | W21: 0 | X21: 0 | Y21: 0 | Z21: 0 | AA21: 0 | AB21: 0 | AC21: 7 | AD21: 1 | AE21: =IF(AD21=0,"",AC21/AD21) -> 7 | AF21: 0 | AG21: 0 | AH21: 0 | AI21: 23 | AJ21: 3 | AK21: =IF(AJ21=0,"",AI21/AJ21) -> 7.6666667 | AL21: 0 | AM21: 0 | AN21: 0 | AO21: 0 | AP21: 0 | AQ21: 0 | AR21: 6 | AS21: 1 | AT21: 0 | AU21: 6 | AV21: 1 | AW21: =IF(AV21=0,"",AU21/AV21) -> 6 | AX21: 0 | AY21: 0 | AZ21: 0 | BA21: 0 | BB21: 0 | BC21: 0 | BD21: 0 | BE21: 0 | BF21: 0 | BG21: 0 | BH21: 0 | BI21: 0 | BJ21: =BG21+BD21+BA21+AX21+AU21+AR21+AO21+AL21+AI21+Q21+N21+K21+H21+E21+AF21+AC21+Z21+W21+T21+B21 -> 404 | BK21: =BH21+BE21+BB21+AY21+AV21+AS21+AP21+AM21+AJ21+R21+O21+L21+I21+F21+AG21+AD21+AA21+X21+U21+C21 -> 62 | BL21: =IF(BK21=0,"",BJ21/BK21) -> 6.516129
A22: 45217 | B22: 38 | C22: 5 | D22: =IF(C22=0,"",B22/C22) -> 7.6 | E22: 8 | F22: 1 | G22: =IF(F22=0,"",E22/F22) -> 8 | H22: 0 | I22: 0 | J22: 0 | K22: 60 | L22: 10 | M22: =IF(L22=0,"",K22/L22) -> 6 | N22: 130 | O22: 24 | P22: =IF(O22=0,"",N22/O22) -> 5.4166667 | Q22: 12 | R22: 2 | S22: =IF(R22=0,"",Q22/R22) -> 6 | T22: 3 | U22: 1 | V22: =IF(U22=0,"",T22/U22) -> 3 | W22: 0 | X22: 0 | Y22: 0 | Z22: 0 | AA22: 0 | AB22: 0 | AC22: 1 | AD22: 1 | AE22: =IF(AD22=0,"",AC22/AD22) -> 1 | AF22: 2 | AG22: 1 | AH22: =IF(AG22=0,"",AF22/AG22) -> 2 | AI22: 25 | AJ22: 3 | AK22: =IF(AJ22=0,"",AI22/AJ22) -> 8.3333333 | AL22: 0 | AM22: 0 | AN22: 0 | AO22: 0 | AP22: 0 | AQ22: 0 | AR22: 0 | AS22: 0 | AT22: 0 | AU22: 0 | AV22: 0 | AW22: 0 | AX22: 6 | AY22: 1 | AZ22: =IF(AY22=0,"",AX22/AY22) -> 6 | BA22: 0 | BB22: 0 | BC22: 0 | BD22: 0 | BE22: 0 | BF22: 0 | BG22: 0 | BH22: 0 | BI22: 0 | BJ22: =BG22+BD22+BA22+AX22+AU22+AR22+AO22+AL22+AI22+Q22+N22+K22+H22+E22+AF22+AC22+Z22+W22+T22+B22 -> 285 | BK22: =BH22+BE22+BB22+AY22+AV22+AS22+AP22+AM22+AJ22+R22+O22+L22+I22+F22+AG22+AD22+AA22+X22+U22+C22 -> 49 | BL22: =IF(BK22=0,"",BJ22/BK22) -> 5.8163265
A23: 45218 | B23: 51 | C23: 6 | D23: =IF(C23=0,"",B23/C23) -> 8.5 | E23: 8 | F23: 1 | G23: =IF(F23=0,"",E23/F23) -> 8 | H23: 0 | I23: 0 | J23: 0 | K23: 40 | L23: 8 | M23: =IF(L23=0,"",K23/L23) -> 5 | N23: 6 | O23: 2 | P23: =IF(O23=0,"",N23/O23) -> 3 | Q23: 0 | R23: 0 | S23: =IF(R23=0,"",Q23/R23) | T23: 2 | U23: 1 | V23: =IF(U23=0,"",T23/U23) -> 2 | W23: 0 | X23: 0 | Y23: 0 | Z23: 0 | AA23: 0 | AB23: 0 | AC23: 0 | AD23: 0 | AE23: 0 | AF23: 0 | AG23: 0 | AH23: 0 | AI23: 6 | AJ23: 1 | AK23: =IF(AJ23=0,"",AI23/AJ23) -> 6 | AL23: 0 | AM23: 0 | AN23: 0 | AO23: 12 | AP23: 2 | AQ23: =IF(AP23=0,"",AO23/AP23) -> 6 | AR23: 7 | AS23: 1 | AT23: =IF(AS23=0,"",AR23/AS23) -> 7 | AU23: 0 | AV23: 0 | AW23: 0 | AX23: 0 | AY23: 0 | AZ23: 0 | BA23: 0 | BB23: 0 | BC23: 0 | BD23: 0 | BE23: 0 | BF23: 0 | BG23: 0 | BH23: 0 | BI23: 0 | BJ23: =BG23+BD23+BA23+AX23+AU23+AR23+AO23+AL23+AI23+Q23+N23+K23+H23+E23+AF23+AC23+Z23+W23+T23+B23 -> 132 | BK23: =BH23+BE23+BB23+AY23+AV23+AS23+AP23+AM23+AJ23+R23+O23+L23+I23+F23+AG23+AD23+AA23+X23+U23+C23 -> 22 | BL23: =IF(BK23=0,"",BJ23/BK23) -> 6
A24: 45219 | B24: 16 | C24: 2 | D24: =IF(C24=0,"",B24/C24) -> 8 | E24: 2 | F24: 1 | G24: =IF(F24=0,"",E24/F24) -> 2 | H24: 0 | I24: 0 | J24: 0 | K24: 14 | L24: 3 | M24: =IF(L24=0,"",K24/L24) -> 4.6666667 | N24: 0 | O24: 0 | P24: =IF(O24=0,"",N24/O24) | Q24: 27 | R24: 4 | S24: =IF(R24=0,"",Q24/R24) -> 6.75 | T24: 3 | U24: 1 | V24: =IF(U24=0,"",T24/U24) -> 3 | W24: 0 | X24: 0 | Y24: 0 | Z24: 0 | AA24: 0 | AB24: 0 | AC24: 0 | AD24: 0 | AE24: 0 | AF24: 0 | AG24: 0 | AH24: 0 | AI24: 8 | AJ24: 1 | AK24: =IF(AJ24=0,"",AI24/AJ24) -> 8 | AL24: 2 | AM24: 1 | AN24: =IF(AM24=0,"",AL24/AM24) -> 2 | AO24: 7 | AP24: 1 | AQ24: =IF(AP24=0,"",AO24/AP24) -> 7 | AR24: 0 | AS24: 0 | AT24: 0 | AU24: 6 | AV24: 1 | AW24: =IF(AV24=0,"",AU24/AV24) -> 6 | AX24: 0 | AY24: 0 | AZ24: 0 | BA24: 0 | BB24: 0 | BC24: 0 | BD24: 0 | BE24: 0 | BF24: 0 | BG24: 0 | BH24: 0 | BI24: 0 | BJ24: =BG24+BD24+BA24+AX24+AU24+AR24+AO24+AL24+AI24+Q24+N24+K24+H24+E24+AF24+AC24+Z24+W24+T24+B24 -> 85 | BK24: =BH24+BE24+BB24+AY24+AV24+AS24+AP24+AM24+AJ24+R24+O24+L24+I24+F24+AG24+AD24+AA24+X24+U24+C24 -> 15 | BL24: =IF(BK24=0,"",BJ24/BK24) -> 5.6666667
A25: 45220 | B25: 90 | C25: 10 | D25: =IF(C25=0,"",B25/C25) -> 9 | E25: 0 | F25: 0 | G25: 0 | H25: 0 | I25: 0 | J25: 0 | K25: 10 | L25: 2 | M25: =IF(L25=0,"",K25/L25) -> 5 | N25: 6 | O25: 1 | P25: =IF(O25=0,"",N25/O25) -> 6 | Q25: 29 | R25: 3 | S25: =IF(R25=0,"",Q25/R25) -> 9.6666667 | T25: 0 | U25: 0 | V25: =IF(U25=0,"",T25/U25) | W25: 0 | X25: 0 | Y25: 0 | Z25: 0 | AA25: 0 | AB25: 0 | AC25: 0 | AD25: 0 | AE25: 0 | AF25: 0 | AG25: 0 | AH25: 0 | AI25: 8 | AJ25: 1 | AK25: =IF(AJ25=0,"",AI25/AJ25) -> 8 | AL25: 0 | AM25: 0 | AN25: 0 | AO25: 0 | AP25: 0 | AQ25: 0 | AR25: 0 | AS25: 0 | AT25: 0 | AU25: 0 | AV25: 0 | AW25: 0 | AX25: 0 | AY25: 0 | AZ25: 0 | BA25: 0 | BB25: 0 | BC25: 0 | BD25: 0 | BE25: 0 | BF25: 0 | BG25: 0 | BH25: 0 | BI25: 0 | BJ25: =BG25+BD25+BA25+AX25+AU25+AR25+AO25+AL25+AI25+Q25+N25+K25+H25+E25+AF25+AC25+Z25+W25+T25+B25 -> 143 | BK25: =BH25+BE25+BB25+AY25+AV25+AS25+AP25+AM25+AJ25+R25+O25+L25+I25+F25+AG25+AD25+AA25+X25+U25+C25 -> 17 | BL25: =IF(BK25=0,"",BJ25/BK25) -> 8.4117647
A26: 45221 | B26: 0 | C26: 0 | D26: 0 | E26: 0 | F26: 0 | G26: 0 | H26: 0 | I26: 0 | J26: 0 | K26: 0 | L26: 0 | M26: 0 | N26: 0 | O26: 0 | P26: =IF(O26=0,"",N26/O26) | Q26: 0 | R26: 0 | S26: =IF(R26=0,"",Q26/R26) | T26: 0 | U26: 0 | V26: =IF(U26=0,"",T26/U26) | W26: 0 | X26: 0 | Y26: 0 | Z26: 0 | AA26: 0 | AB26: 0 | AC26: 0 | AD26: 0 | AE26: 0 | AF26: 0 | AG26: 0 | AH26: 0 | AI26: 49 | AJ26: 7 | AK26: =IF(AJ26=0,"",AI26/AJ26) -> 7 | AL26: 0 | AM26: 0 | AN26: 0 | AO26: 0 | AP26: 0 | AQ26: 0 | AR26: 7 | AS26: 1 | AT26: =IF(AS26=0,"",AR26/AS26) -> 7 | AU26: 0 | AV26: 0 | AW26: 0 | AX26: 4 | AY26: 1 | AZ26: =IF(AY26=0,"",AX26/AY26) -> 4 | BA26: 0 | BB26: 0 | BC26: 0 | BD26: 0 | BE26: 0 | BF26: 0 | BG26: 0 | BH26: 0 | BI26: 0 | BJ26: =BG26+BD26+BA26+AX26+AU26+AR26+AO26+AL26+AI26+Q26+N26+K26+H26+E26+AF26+AC26+Z26+W26+T26+B26 -> 60 | BK26: =BH26+BE26+BB26+AY26+AV26+AS26+AP26+AM26+AJ26+R26+O26+L26+I26+F26+AG26+AD26+AA26+X26+U26+C26 -> 9 | BL26: =IF(BK26=0,"",BJ26/BK26) -> 6.6666667
A27: 45222 | B27: 59 | C27: 7 | D27: =IF(C27=0,"",B27/C27) -> 8.4285714 | E27: 13 | F27: 2 | G27: =IF(F27=0,"",E27/F27) -> 6.5 | H27: 0 | I27: 0 | J27: 0 | K27: 17 | L27: 3 | M27: =IF(L27=0,"",K27/L27) -> 5.6666667 | N27: 241 | O27: 41 | P27: =IF(O27=0,"",N27/O27) -> 5.8780488 | Q27: 0 | R27: 0 | S27: =IF(R27=0,"",Q27/R27) | T27: 7 | U27: 1 | V27: =IF(U27=0,"",T27/U27) -> 7 | W27: 0 | X27: 0 | Y27: 0 | Z27: 0 | AA27: 0 | AB27: 0 | AC27: 0 | AD27: 0 | AE27: 0 | AF27: 2 | AG27: 1 | AH27: =IF(AG27=0,"",AF27/AG27) -> 2 | AI27: 6 | AJ27: 1 | AK27: =IF(AJ27=0,"",AI27/AJ27) -> 6 | AL27: 0 | AM27: 0 | AN27: 0 | AO27: 0 | AP27: 0 | AQ27: 0 | AR27: 0 | AS27: 0 | AT27: 0 | AU27: 0 | AV27: 0 | AW27: 0 | AX27: 0 | AY27: 0 | AZ27: 0 | BA27: 0 | BB27: 0 | BC27: 0 | BD27: 0 | BE27: 0 | BF27: 0 | BG27: 0 | BH27: 0 | BI27: 0 | BJ27: =BG27+BD27+BA27+AX27+AU27+AR27+AO27+AL27+AI27+Q27+N27+K27+H27+E27+AF27+AC27+Z27+W27+T27+B27 -> 345 | BK27: =BH27+BE27+BB27+AY27+AV27+AS27+AP27+AM27+AJ27+R27+O27+L27+I27+F27+AG27+AD27+AA27+X27+U27+C27 -> 56 | BL27: =IF(BK27=0,"",BJ27/BK27) -> 6.1607143
A28: 45223 | B28: 51 | C28: 7 | D28: =IF(C28=0,"",B28/C28) -> 7.2857143 | E28: 7 | F28: 1 | G28: =IF(F28=0,"",E28/F28) -> 7 | H28: 0 | I28: 0 | J28: 0 | K28: 62 | L28: 11 | M28: =IF(L28=0,"",K28/L28) -> 5.6363636 | N28: 0 | O28: 0 | P28: =IF(O28=0,"",N28/O28) | Q28: 17 | R28: 2 | S28: =IF(R28=0,"",Q28/R28) -> 8.5 | T28: 1 | U28: 1 | V28: =IF(U28=0,"",T28/U28) -> 1 | W28: 0 | X28: 0 | Y28: =IF(X28=0,"",W28/X28) | Z28: 2 | AA28: 1 | AB28: =IF(AA28=0,"",Z28/AA28) -> 2 | AC28: 0 | AD28: 0 | AE28: 0 | AF28: 1 | AG28: 1 | AH28: =IF(AG28=0,"",AF28/AG28) -> 1 | AI28: 26 | AJ28: 4 | AK28: =IF(AJ28=0,"",AI28/AJ28) -> 6.5 | AL28: 0 | AM28: 0 | AN28: 0 | AO28: 0 | AP28: 0 | AQ28: 0 | AR28: 0 | AS28: 0 | AT28: =IF(AS28=0,"",AR28/AS28) | AU28: 0 | AV28: 0 | AW28: 0 | AX28: 0 | AY28: 0 | AZ28: 0 | BA28: 0 | BB28: 0 | BC28: 0 | BD28: 0 | BE28: 0 | BF28: 0 | BG28: 0 | BH28: 0 | BI28: 0 | BJ28: =BG28+BD28+BA28+AX28+AU28+AR28+AO28+AL28+AI28+Q28+N28+K28+H28+E28+AF28+AC28+Z28+W28+T28+B28 -> 167 | BK28: =BH28+BE28+BB28+AY28+AV28+AS28+AP28+AM28+AJ28+R28+O28+L28+I28+F28+AG28+AD28+AA28+X28+U28+C28 -> 28 | BL28: =IF(BK28=0,"",BJ28/BK28) -> 5.9642857
A29: 45224 | B29: 17 | C29: 2 | D29: =IF(C29=0,"",B29/C29) -> 8.5 | E29: 7 | F29: 1 | G29: =IF(F29=0,"",E29/F29) -> 7 | H29: 0 | I29: 0 | J29: 0 | K29: 32 | L29: 6 | M29: =IF(L29=0,"",K29/L29) -> 5.3333333 | N29: 0 | O29: 0 | P29: =IF(O29=0,"",N29/O29) | Q29: 25 | R29: 3 | S29: =IF(R29=0,"",Q29/R29) -> 8.3333333 | T29: 0 | U29: 0 | V29: =IF(U29=0,"",T29/U29) | W29: 0 | X29: 0 | Y29: 0 | Z29: 0 | AA29: 0 | AB29: 0 | AC29: 0 | AD29: 0 | AE29: 0 | AF29: 1 | AG29: 1 | AH29: =IF(AG29=0,"",AF29/AG29) -> 1 | AI29: 13 | AJ29: 2 | AK29: =IF(AJ29=0,"",AI29/AJ29) -> 6.5 | AL29: 9 | AM29: 1 | AN29: =IF(AM29=0,"",AL29/AM29) -> 9 | AO29: 0 | AP29: 0 | AQ29: 0 | AR29: 6 | AS29: 1 | AT29: =IF(AS29=0,"",AR29/AS29) -> 6 | AU29: 0 | AV29: 0 | AW29: 0 | AX29: 0 | AY29: 0 | AZ29: 0 | BA29: 0 | BB29: 0 | BC29: 0 | BD29: 0 | BE29: 0 | BF29: 0 | BG29: 0 | BH29: 0 | BI29: 0 | BJ29: =BG29+BD29+BA29+AX29+AU29+AR29+AO29+AL29+AI29+Q29+N29+K29+H29+E29+AF29+AC29+Z29+W29+T29+B29 -> 110 | BK29: =BH29+BE29+BB29+AY29+AV29+AS29+AP29+AM29+AJ29+R29+O29+L29+I29+F29+AG29+AD29+AA29+X29+U29+C29 -> 17 | BL29: =IF(BK29=0,"",BJ29/BK29) -> 6.4705882
A30: 45225 | B30: 17 | C30: 2 | D30: =IF(C30=0,"",B30/C30) -> 8.5 | E30: 0 | F30: 0 | G30: 0 | H30: 22 | I30: 3 | J30: =IF(I30=0,"",H30/I30) -> 7.3333333 | K30: 23 | L30: 4 | M30: =IF(L30=0,"",K30/L30) -> 5.75 | N30: 431 | O30: 70 | P30: =IF(O30=0,"",N30/O30) -> 6.1571429 | Q30: 0 | R30: 0 | S30: =IF(R30=0,"",Q30/R30) | T30: 0 | U30: 0 | V30: =IF(U30=0,"",T30/U30) | W30: 0 | X30: 0 | Y30: 0 | Z30: 0 | AA30: 0 | AB30: 0 | AC30: 0 | AD30: 0 | AE30: 0 | AF30: 0 | AG30: 0 | AH30: 0 | AI30: 6 | AJ30: 1 | AK30: =IF(AJ30=0,"",AI30/AJ30) -> 6 | AL30: 0 | AM30: 0 | AN30: 0 | AO30: 0 | AP30: 0 | AQ30: 0 | AR30: 0 | AS30: 0 | AT30: 0 | AU30: 0 | AV30: 0 | AW30: 0 | AX30: 0 | AY30: 0 | AZ30: 0 | BA30: 0 | BB30: 0 | BC30: 0 | BD30: 0 | BE30: 0 | BF30: 0 | BG30: 0 | BH30: 0 | BI30: 0 | BJ30: =BG30+BD30+BA30+AX30+AU30+AR30+AO30+AL30+AI30+Q30+N30+K30+H30+E30+AF30+AC30+Z30+W30+T30+B30 -> 499 | BK30: =BH30+BE30+BB30+AY30+AV30+AS30+AP30+AM30+AJ30+R30+O30+L30+I30+F30+AG30+AD30+AA30+X30+U30+C30 -> 80 | BL30: =IF(BK30=0,"",BJ30/BK30) -> 6.2375
A31: 45226 | B31: 78 | C31: 9 | D31: =IF(C31=0,"",B31/C31) -> 8.6666667 | E31: 16 | F31: 2 | G31: =IF(F31=0,"",E31/F31) -> 8 | H31: 0 | I31: 0 | J31: 0 | K31: 28 | L31: 5 | M31: =IF(L31=0,"",K31/L31) -> 5.6 | N31: 191 | O31: 32 | P31: =IF(O31=0,"",N31/O31) -> 5.96875 | Q31: 0 | R31: 0 | S31: =IF(R31=0,"",Q31/R31) | T31: 5 | U31: 1 | V31: =IF(U31=0,"",T31/U31) -> 5 | W31: 0 | X31: 0 | Y31: 0 | Z31: 0 | AA31: 0 | AB31: 0 | AC31: 0 | AD31: 0 | AE31: 0 | AF31: 5 | AG31: 1 | AH31: =IF(AG31=0,"",AF31/AG31) -> 5 | AI31: 27 | AJ31: 4 | AK31: =IF(AJ31=0,"",AI31/AJ31) -> 6.75 | AL31: 0 | AM31: 0 | AN31: 0 | AO31: 0 | AP31: 0 | AQ31: 0 | AR31: 0 | AS31: 0 | AT31: 0 | AU31: 6 | AV31: 1 | AW31: =IF(AV31=0,"",AU31/AV31) -> 6 | AX31: 14 | AY31: 2 | AZ31: =IF(AY31=0,"",AX31/AY31) -> 7 | BA31: 0 | BB31: 0 | BC31: 0 | BD31: 0 | BE31: 0 | BF31: 0 | BG31: 0 | BH31: 0 | BI31: 0 | BJ31: =BG31+BD31+BA31+AX31+AU31+AR31+AO31+AL31+AI31+Q31+N31+K31+H31+E31+AF31+AC31+Z31+W31+T31+B31 -> 370 | BK31: =BH31+BE31+BB31+AY31+AV31+AS31+AP31+AM31+AJ31+R31+O31+L31+I31+F31+AG31+AD31+AA31+X31+U31+C31 -> 57 | BL31: =IF(BK31=0,"",BJ31/BK31) -> 6.4912281
A32: 45227 | B32: 49 | C32: 6 | D32: =IF(C32=0,"",B32/C32) -> 8.1666667 | E32: 0 | F32: 0 | G32: 0 | H32: 0 | I32: 0 | J32: 0 | K32: 53 | L32: 11 | M32: =IF(L32=0,"",K32/L32) -> 4.8181818 | N32: 13 | O32: 3 | P32: =IF(O32=0,"",N32/O32) -> 4.3333333 | Q32: 0 | R32: 0 | S32: =IF(R32=0,"",Q32/R32) | T32: 0 | U32: 0 | V32: =IF(U32=0,"",T32/U32) | W32: 0 | X32: 0 | Y32: 0 | Z32: 0 | AA32: 0 | AB32: 0 | AC32: 0 | AD32: 0 | AE32: 0 | AF32: 0 | AG32: 0 | AH32: 0 | AI32: 26 | AJ32: 4 | AK32: =IF(AJ32=0,"",AI32/AJ32) -> 6.5 | AL32: 10 | AM32: 1 | AN32: =IF(AM32=0,"",AL32/AM32) -> 10 | AO32: 0 | AP32: 0 | AQ32: 0 | AR32: 0 | AS32: 0 | AT32: 0 | AU32: 0 | AV32: 0 | AW32: 0 | AX32: 0 | AY32: 0 | AZ32: 0 | BA32: 0 | BB32: 0 | BC32: 0 | BD32: 0 | BE32: 0 | BF32: 0 | BG32: 0 | BH32: 0 | BI32: 0 | BJ32: =BG32+BD32+BA32+AX32+AU32+AR32+AO32+AL32+AI32+Q32+N32+K32+H32+E32+AF32+AC32+Z32+W32+T32+B32 -> 151 | BK32: =BH32+BE32+BB32+AY32+AV32+AS32+AP32+AM32+AJ32+R32+O32+L32+I32+F32+AG32+AD32+AA32+X32+U32+C32 -> 25 | BL32: =IF(BK32=0,"",BJ32/BK32) -> 6.04
A33: 45228 | B33: 42 | C33: 5 | D33: =IF(C33=0,"",B33/C33) -> 8.4 | E33: 0 | F33: 0 | G33: 0 | H33: 0 | I33: 0 | J33: 0 | K33: 0 | L33: 0 | M33: 0 | N33: 0 | O33: 0 | P33: =IF(O33=0,"",N33/O33) | Q33: 0 | R33: 0 | S33: =IF(R33=0,"",Q33/R33) | T33: 0 | U33: 0 | V33: =IF(U33=0,"",T33/U33) | W33: 0 | X33: 0 | Y33: 0 | Z33: 0 | AA33: 0 | AB33: 0 | AC33: 0 | AD33: 0 | AE33: 0 | AF33: 0 | AG33: 0 | AH33: 0 | AI33: 12 | AJ33: 2 | AK33: =IF(AJ33=0,"",AI33/AJ33) -> 6 | AL33: 0 | AM33: 0 | AN33: 0 | AO33: 0 | AP33: 0 | AQ33: 0 | AR33: 6 | AS33: 1 | AT33: =IF(AS33=0,"",AR33/AS33) -> 6 | AU33: 0 | AV33: 0 | AW33: 0 | AX33: 5 | AY33: 1 | AZ33: =IF(AY33=0,"",AX33/AY33) -> 5 | BA33: 0 | BB33: 0 | BC33: 0 | BD33: 0 | BE33: 0 | BF33: 0 | BG33: 0 | BH33: 0 | BI33: 0 | BJ33: =BG33+BD33+BA33+AX33+AU33+AR33+AO33+AL33+AI33+Q33+N33+K33+H33+E33+AF33+AC33+Z33+W33+T33+B33 -> 65 | BK33: =BH33+BE33+BB33+AY33+AV33+AS33+AP33+AM33+AJ33+R33+O33+L33+I33+F33+AG33+AD33+AA33+X33+U33+C33 -> 9 | BL33: =IF(BK33=0,"",BJ33/BK33) -> 7.2222222
A34: 45229 | B34: 9 | C34: 1 | D34: =IF(C34=0,"",B34/C34) -> 9 | E34: 0 | F34: 0 | G34: 0 | H34: 0 | I34: 0 | J34: 0 | K34: 37 | L34: 7 | M34: =IF(L34=0,"",K34/L34) -> 5.2857143 | N34: 1 | O34: 1 | P34: =IF(O34=0,"",N34/O34) -> 1 | Q34: 66 | R34: 7 | S34: =IF(R34=0,"",Q34/R34) -> 9.4285714 | T34: 2 | U34: 1 | V34: =IF(U34=0,"",T34/U34) -> 2 | W34: 0 | X34: 0 | Y34: 0 | Z34: 0 | AA34: 0 | AB34: 0 | AC34: 0 | AD34: 0 | AE34: 0 | AF34: 0 | AG34: 0 | AH34: 0 | AI34: 8 | AJ34: 1 | AK34: =IF(AJ34=0,"",AI34/AJ34) -> 8 | AL34: 0 | AM34: 0 | AN34: 0 | AO34: 0 | AP34: 0 | AQ34: 0 | AR34: 0 | AS34: 0 | AT34: 0 | AU34: 14 | AV34: 2 | AW34: =IF(AV34=0,"",AU34/AV34) -> 7 | AX34: 0 | AY34: 0 | AZ34: 0 | BA34: 0 | BB34: 0 | BC34: 0 | BD34: 0 | BE34: 0 | BF34: 0 | BG34: 0 | BH34: 0 | BI34: 0 | BJ34: =BG34+BD34+BA34+AX34+AU34+AR34+AO34+AL34+AI34+Q34+N34+K34+H34+E34+AF34+AC34+Z34+W34+T34+B34 -> 137 | BK34: =BH34+BE34+BB34+AY34+AV34+AS34+AP34+AM34+AJ34+R34+O34+L34+I34+F34+AG34+AD34+AA34+X34+U34+C34 -> 20 | BL34: =IF(BK34=0,"",BJ34/BK34) -> 6.85
A35: 45230 | B35: 34 | C35: 4 | D35: =IF(C35=0,"",B35/C35) -> 8.5 | E35: 8 | F35: 1 | G35: =IF(F35=0,"",E35/F35) -> 8 | J35: =IF(I35=0,"",H35/I35) | K35: 32 | L35: 8 | M35: =IF(L35=0,"",K35/L35) -> 4 | N35: 0 | O35: 0 | P35: =IF(O35=0,"",N35/O35) | Q35: 18 | R35: 2 | S35: =IF(R35=0,"",Q35/R35) -> 9 | T35: 0 | U35: 0 | V35: =IF(U35=0,"",T35/U35) | W35: 0 | X35: 0 | Y35: 0 | Z35: 1 | AA35: 1 | AB35: =IF(AA35=0,"",Z35/AA35) -> 1 | AC35: 0 | AD35: 0 | AE35: 0 | AF35: 0 | AG35: 0 | AH35: 0 | AI35: 7 | AJ35: 1 | AK35: =IF(AJ35=0,"",AI35/AJ35) -> 7 | AL35: 0 | AM35: 0 | AN35: 0 | AO35: 0 | AP35: 0 | AQ35: 0 | AR35: 0 | AS35: 0 | AT35: 0 | AU35: 0 | AV35: 0 | AW35: 0 | AX35: 0 | AY35: 0 | AZ35: 0 | BA35: 0 | BB35: 0 | BC35: 0 | BD35: 0 | BE35: 0 | BF35: 0 | BG35: 0 | BH35: 0 | BI35: 0 | BJ35: =BG35+BD35+BA35+AX35+AU35+AR35+AO35+AL35+AI35+Q35+N35+K35+H35+E35+AF35+AC35+Z35+W35+T35+B35 -> 100 | BK35: =BH35+BE35+BB35+AY35+AV35+AS35+AP35+AM35+AJ35+R35+O35+L35+I35+F35+AG35+AD35+AA35+X35+U35+C35 -> 17 | BL35: =IF(BK35=0,"",BJ35/BK35) -> 5.8823529
A36: Total | B36: =SUM(B5:B35) -> 1556 | C36: =SUM(C5:C35) -> 185 | D36: =B36/C36 -> 8.4108108 | E36: =SUM(E5:E35) -> 149 | F36: =SUM(F5:F35) -> 22 | G36: =E36/F36 -> 6.7727273 | H36: =SUM(H5:H35) -> 135 | I36: =SUM(I5:I35) -> 18 | J36: =H36/I36 -> 7.5 | K36: =SUM(K5:K35) -> 840 | L36: =SUM(L5:L35) -> 153 | M36: =K36/L36 -> 5.4901961 | N36: =SUM(N5:N35) -> 2685 | O36: =SUM(O5:O35) -> 465 | P36: =N36/O36 -> 5.7741935 | Q36: =SUM(Q5:Q35) -> 300 | R36: =SUM(R5:R35) -> 38 | S36: =Q36/R36 -> 7.8947368 | T36: =SUM(T5:T35) -> 72 | U36: =SUM(U5:U35) -> 18 | V36: =T36/U36 -> 4 | W36: =SUM(W5:W35) -> 0 | X36: =SUM(X5:X35) -> 0 | Y36: =W36/X36 -> #DIV/0! | Z36: =SUM(Z5:Z35) -> 6 | AA36: =SUM(AA5:AA35) -> 5 | AB36: =Z36/AA36 -> 1.2 | AC36: =SUM(AC5:AC35) -> 8 | AD36: =SUM(AD5:AD35) -> 2 | AE36: =AC36/AD36 -> 4 | AF36: =SUM(AF5:AF35) -> 39 | AG36: =SUM(AG5:AG35) -> 13 | AH36: =AF36/AG36 -> 3 | AI36: =SUM(AI5:AI35) -> 626 | AJ36: =SUM(AJ5:AJ35) -> 84 | AK36: =AI36/AJ36 -> 7.452381 | AL36: =SUM(AL5:AL35) -> 21 | AM36: =SUM(AM5:AM35) -> 3 | AN36: =AL36/AM36 -> 7 | AO36: =SUM(AO5:AO35) -> 19 | AP36: =SUM(AP5:AP35) -> 3 | AQ36: =AO36/AP36 -> 6.3333333 | AR36: =SUM(AR5:AR35) -> 57 | AS36: =SUM(AS5:AS35) -> 9 | AT36: =AR36/AS36 -> 6.3333333 | AU36: =SUM(AU5:AU35) -> 33 | AV36: =SUM(AV5:AV35) -> 6 | AW36: =AU36/AV36 -> 5.5 | AX36: =SUM(AX5:AX35) -> 134 | AY36: =SUM(AY5:AY35) -> 21 | AZ36: =AX36/AY36 -> 6.3809524 | BA36: =SUM(BA5:BA35) -> 0 | BB36: =SUM(BB5:BB35) -> 0 | BC36: =BA36/BB36 -> #DIV/0! | BD36: =SUM(BD5:BD35) -> 0 | BE36: =SUM(BE5:BE35) -> 0 | BF36: =BD36/BE36 -> #DIV/0! | BG36: =SUM(BG5:BG35) -> 3 | BH36: =SUM(BH5:BH35) -> 2 | BI36: =BG36/BH36 -> 1.5 | BJ36: =SUM(BJ5:BJ35) -> 6683 | BK36: =SUM(BK5:BK35) -> 1047 | BL36: =IF(BK36=0,"",BJ36/BK36) -> 6.382999

Sheet Nov 2023
A1: PAYLOAD REPORT BY ROUTE AND MONTH NOV 2023
C2: Aversen | F2: Aversen | I2: Aversen | L2: Aversen | O2: Jerome | R2: Jerome | U2: Jerome | X2: Ansar | AA2: Ansar | AD2: Ansar | AG2: Ansar | AJ2: Ansar | AM2: Brent | AP2: Brent | AS2: Brent | AV2: Brent | AY2: Brent | BB2: Sune | BE2: Sune | BH2: Sune | BK2: Sune | BM2: Total vehicles
B3: Route Kzn - Western Cape | E3: Route Kzn - Northern Cape | H3: Route Kzn - Gauteng | K3: Route Kzn - Other | N3: Route Kzn - Kzn Dealer | Q3: Route DCT - VDC / Other S/Yard | T3: Route KZN - Maputo TTAF/Other | W3: Route Western Cape to PE | Z3: Route Western Cape to EL | AC3: Route Western Cape to Kzn | AF3: Route Western Cape to GP | AI3: Route Western Cape to Other | AL3: Route EC - Kzn | AO3: Route EC - Western Cape | AR3: Route EC - Gauteng | AU3: Route EC- Freestate | AX3: Route EC - Maputo | BA3: Route Gauteng - Kzn | BD3: Route Gauteng - Eastern Cape | BG3: Route Gauteng - Western Cape | BJ3: Route Gauteng - Other | BM3: TOTALS
A4: DAY DATE | B4: Total vehicles | C4: Total Carriers | D4: Payload | E4: Total vehicles | F4: Total Carriers | G4: Payload | H4: Total vehicles | I4: Total Carriers | J4: Payload | K4: Total vehicles | L4: Total Carriers | M4: Payload | N4: Total vehicles | O4: Total Carriers | P4: Payload | Q4: Total vehicles | R4: Total Carriers | S4: Payload | T4: Total vehicles | U4: Total Carriers | V4: Payload | W4: Total vehicles | X4: Total Carriers | Y4: Payload | Z4: Total vehicles | AA4: Total Carriers | AB4: Payload | AC4: Total vehicles | AD4: Total Carriers | AE4: Payload | AF4: Total vehicles | AG4: Total Carriers | AH4: Payload | AI4: Total vehicles | AJ4: Total Carriers | AK4: Payload | AL4: Total vehicles | AM4: Total Carriers | AN4: Payload | AO4: Total vehicles | AP4: Total Carriers | AQ4: Payload | AR4: Total vehicles | AS4: Total Carriers | AT4: Payload | AU4: Total vehicles | AV4: Total Carriers | AW4: Payload | AX4: Total vehicles | AY4: Total Carriers | AZ4: Payload | BA4: Total vehicles | BB4: Total Carriers | BC4: Payload | BD4: Total vehicles | BE4: Total Carriers | BF4: Payload | BG4: Total vehicles | BH4: Total Carriers | BI4: Payload | BJ4: Total vehicles | BK4: Total Carriers | BL4: Payload | BM4: Total vehicles | BN4: Total Carriers | BO4: Payload
A5: 45231 | B5: 68 | C5: 9 | D5: =IF(C5=0,"",B5/C5) -> 7.5555556 | E5: 0 | F5: 0 | G5: =IF(F5=0,"-",E5/F5) -> - | H5: 0 | I5: 0 | J5: =IF(I5=0,"-",H5/I5) -> - | K5: 0 | L5: 0 | M5: =IF(L5=0,"-",K5/L5) -> - | N5: 38 | O5: 7 | P5: =IF(O5=0,"",N5/O5) -> 5.4285714 | Q5: 214 | R5: 52 | S5: =IF(R5=0,"",Q5/R5) -> 4.1153846 | T5: 0 | U5: 0 | V5: =IF(U5=0,"-",T5/U5) -> - | W5: 1 | X5: 1 | Y5: =IF(X5=0,"",W5/X5) -> 1 | Z5: 0 | AA5: 0 | AB5: =IF(AA5=0,"-",Z5/AA5) -> - | AC5: 0 | AD5: 0 | AE5: =IF(AD5=0,"-",AC5/AD5) -> - | AF5: 0 | AG5: 0 | AH5: =IF(AG5=0,"-",AF5/AG5) -> - | AI5: 1 | AJ5: 1 | AK5: =IF(AJ5=0,"",AI5/AJ5) -> 1 | AL5: 47 | AM5: 7 | AN5: =IF(AM5=0,"",AL5/AM5) -> 6.7142857 | AO5: 0 | AP5: 0 | AQ5: =IF(AP5=0,"-",AO5/AP5) -> - | AR5: 0 | AS5: 0 | AT5: =IF(AS5=0,"-",AR5/AS5) -> - | AU5: 6 | AV5: 1 | AW5: =IF(AV5=0,"",AU5/AV5) -> 6 | AX5: 0 | AY5: 0 | AZ5: =IF(AY5=0,"-",AX5/AY5) -> - | BA5: 0 | BB5: 0 | BC5: =IF(BB5=0,"-",BA5/BB5) -> - | BD5: 0 | BE5: 0 | BF5: =IF(BE5=0,"-",BD5/BE5) -> - | BG5: 0 | BH5: 0 | BI5: =IF(BH5=0,"-",BG5/BH5) -> - | BJ5: 0 | BK5: 0 | BL5: =IF(BK5=0,"",BJ5/BK5) | BM5: =BJ5+BG5+BD5+BA5+AX5+AU5+AR5+AO5+AL5+K5+Q5+N5+H5+E5+AI5+AF5+AC5+Z5+W5+B5 -> 375 | BN5: =BK5+BH5+BE5+BB5+AY5+AV5+AS5+AP5+AM5+L5+R5+O5+I5+F5+AJ5+AG5+AD5+AA5+X5+C5 -> 78 | BO5: =IF(BN5=0,"",BM5/BN5) -> 4.8076923
A6: 45232 | B6: 39 | C6: 6 | D6: =IF(C6=0,"",B6/C6) -> 6.5 | E6: 14 | F6: 2 | G6: =IF(F6=0,"",E6/F6) -> 7 | H6: 0 | I6: 0 | J6: =IF(I6=0,"-",H6/I6) -> - | K6: 0 | L6: 0 | M6: =IF(L6=0,"-",K6/L6) -> - | N6: 20 | O6: 5 | P6: =IF(O6=0,"",N6/O6) -> 4 | Q6: 149 | R6: 35 | S6: =IF(R6=0,"",Q6/R6) -> 4.2571429 | T6: 0 | U6: 0 | V6: =IF(U6=0,"-",T6/U6) -> - | W6: 6 | X6: 1 | Y6: =IF(X6=0,"",W6/X6) -> 6 | Z6: 0 | AA6: 0 | AB6: =IF(AA6=0,"-",Z6/AA6) -> - | AC6: 5 | AD6: 1 | AE6: =IF(AD6=0,"-",AC6/AD6) -> 5 | AF6: 0 | AG6: 0 | AH6: =IF(AG6=0,"-",AF6/AG6) -> - | AI6: 2 | AJ6: 2 | AK6: =IF(AJ6=0,"",AI6/AJ6) -> 1 | AL6: 20 | AM6: 3 | AN6: =IF(AM6=0,"",AL6/AM6) -> 6.6666667 | AO6: 0 | AP6: 0 | AQ6: =IF(AP6=0,"-",AO6/AP6) -> - | AR6: 0 | AS6: 0 | AT6: =IF(AS6=0,"-",AR6/AS6) -> - | AU6: 0 | AV6: 0 | AW6: =IF(AV6=0,"-",AU6/AV6) -> - | AX6: 0 | AY6: 0 | AZ6: =IF(AY6=0,"-",AX6/AY6) -> - | BA6: 0 | BB6: 0 | BC6: =IF(BB6=0,"-",BA6/BB6) -> - | BD6: 0 | BE6: 0 | BF6: =IF(BE6=0,"-",BD6/BE6) -> - | BG6: 0 | BH6: 0 | BI6: =IF(BH6=0,"-",BG6/BH6) -> - | BJ6: 0 | BK6: 0 | BL6: =IF(BK6=0,"-",BJ6/BK6) -> - | BM6: =BJ6+BG6+BD6+BA6+AX6+AU6+AR6+AO6+AL6+K6+Q6+N6+H6+E6+AI6+AF6+AC6+Z6+W6+B6 -> 255 | BN6: =BK6+BH6+BE6+BB6+AY6+AV6+AS6+AP6+AM6+L6+R6+O6+I6+F6+AJ6+AG6+AD6+AA6+X6+C6 -> 55 | BO6: =IF(BN6=0,"",BM6/BN6) -> 4.6363636
A7: 45233 | B7: 32 | C7: 4 | D7: =IF(C7=0,"",B7/C7) -> 8 | E7: 8 | F7: 1 | G7: =IF(F7=0,"",E7/F7) -> 8 | H7: 23 | I7: 3 | J7: =IF(I7=0,"",H7/I7) -> 7.6666667 | K7: 0 | L7: 0 | M7: =IF(L7=0,"-",K7/L7) -> - | N7: 15 | O7: 3 | P7: =IF(O7=0,"",N7/O7) -> 5 | Q7: 0 | R7: 0 | S7: =IF(R7=0,"-",Q7/R7) -> - | T7: 0 | U7: 0 | V7: =IF(U7=0,"-",T7/U7) -> - | W7: 0 | X7: 0 | Y7: =IF(X7=0,"-",W7/X7) -> - | Z7: 0 | AA7: 0 | AB7: =IF(AA7=0,"-",Z7/AA7) -> - | AC7: 4 | AD7: 1 | AE7: =IF(AD7=0,"-",AC7/AD7) -> 4 | AF7: 0 | AG7: 0 | AH7: =IF(AG7=0,"-",AF7/AG7) -> - | AI7: 15 | AJ7: 4 | AK7: =IF(AJ7=0,"",AI7/AJ7) -> 3.75 | AL7: 7 | AM7: 1 | AN7: =IF(AM7=0,"",AL7/AM7) -> 7 | AO7: 0 | AP7: 0 | AQ7: =IF(AP7=0,"-",AO7/AP7) -> - | AR7: 0 | AS7: 0 | AT7: =IF(AS7=0,"-",AR7/AS7) -> - | AU7: 0 | AV7: 0 | AW7: =IF(AV7=0,"-",AU7/AV7) -> - | AX7: 0 | AY7: 0 | AZ7: =IF(AY7=0,"-",AX7/AY7) -> - | BA7: 0 | BB7: 0 | BC7: =IF(BB7=0,"-",BA7/BB7) -> - | BD7: 0 | BE7: 0 | BF7: =IF(BE7=0,"-",BD7/BE7) -> - | BG7: 0 | BH7: 0 | BI7: =IF(BH7=0,"-",BG7/BH7) -> - | BJ7: 0 | BK7: 0 | BL7: =IF(BK7=0,"-",BJ7/BK7) -> - | BM7: =BJ7+BG7+BD7+BA7+AX7+AU7+AR7+AO7+AL7+K7+Q7+N7+H7+E7+AI7+AF7+AC7+Z7+W7+B7 -> 104 | BN7: =BK7+BH7+BE7+BB7+AY7+AV7+AS7+AP7+AM7+L7+R7+O7+I7+F7+AJ7+AG7+AD7+AA7+X7+C7 -> 17 | BO7: =IF(BN7=0,"",BM7/BN7) -> 6.1176471
A8: 45234 | B8: 32 | C8: 4 | D8: =IF(C8=0,"",B8/C8) -> 8 | E8: 0 | F8: 0 | G8: =IF(F8=0,"-",E8/F8) -> - | H8: 0 | I8: 0 | J8: =IF(I8=0,"-",H8/I8) -> - | K8: 0 | L8: 0 | M8: =IF(L8=0,"-",K8/L8) -> - | N8: 18 | O8: 4 | P8: =IF(O8=0,"",N8/O8) -> 4.5 | Q8: 0 | R8: 0 | S8: =IF(R8=0,"-",Q8/R8) -> - | T8: 6 | U8: 1 | V8: =IF(U8=0,"-",T8/U8) -> 6 | W8: 0 | X8: 0 | Y8: =IF(X8=0,"-",W8/X8) -> - | Z8: 0 | AA8: 0 | AB8: =IF(AA8=0,"-",Z8/AA8) -> - | AC8: 0 | AD8: 0 | AE8: =IF(AD8=0,"-",AC8/AD8) -> - | AF8: 0 | AG8: 0 | AH8: =IF(AG8=0,"-",AF8/AG8) -> - | AI8: 0 | AJ8: 0 | AK8: =IF(AJ8=0,"-",AI8/AJ8) -> - | AL8: 0 | AM8: 0 | AN8: =IF(AM8=0,"-",AL8/AM8) -> - | AO8: 0 | AP8: 0 | AQ8: =IF(AP8=0,"-",AO8/AP8) -> - | AR8: 0 | AS8: 0 | AT8: =IF(AS8=0,"-",AR8/AS8) -> - | AU8: 0 | AV8: 0 | AW8: =IF(AV8=0,"-",AU8/AV8) -> - | AX8: 6 | AY8: 1 | AZ8: =IF(AY8=0,"-",AX8/AY8) -> 6 | BA8: 24 | BB8: 3 | BC8: =IF(BB8=0,"",BA8/BB8) -> 8 | BD8: 0 | BE8: 0 | BF8: =IF(BE8=0,"-",BD8/BE8) -> - | BG8: 0 | BH8: 0 | BI8: =IF(BH8=0,"-",BG8/BH8) -> - | BJ8: 0 | BK8: 0 | BL8: =IF(BK8=0,"-",BJ8/BK8) -> - | BM8: =BJ8+BG8+BD8+BA8+AX8+AU8+AR8+AO8+AL8+K8+Q8+N8+H8+E8+AI8+AF8+AC8+Z8+W8+B8 -> 80 | BN8: =BK8+BH8+BE8+BB8+AY8+AV8+AS8+AP8+AM8+L8+R8+O8+I8+F8+AJ8+AG8+AD8+AA8+X8+C8 -> 12 | BO8: =IF(BN8=0,"",BM8/BN8) -> 6.6666667
A9: 45235 | B9: 0 | C9: 0 | D9: =IF(C9=0,"-",B9/C9) -> - | E9: 0 | F9: 0 | G9: =IF(F9=0,"-",E9/F9) -> - | H9: 0 | I9: 0 | J9: =IF(I9=0,"-",H9/I9) -> - | K9: 0 | L9: 0 | M9: =IF(L9=0,"-",K9/L9) -> - | N9: 0 | O9: 0 | P9: =IF(O9=0,"-",N9/O9) -> - | Q9: 414 | R9: 55 | S9: =IF(R9=0,"",Q9/R9) -> 7.5272727 | T9: 0 | U9: 0 | V9: =IF(U9=0,"-",T9/U9) -> - | W9: 0 | X9: 0 | Y9: =IF(X9=0,"-",W9/X9) -> - | Z9: 0 | AA9: 0 | AB9: =IF(AA9=0,"-",Z9/AA9) -> - | AC9: 0 | AD9: 0 | AE9: =IF(AD9=0,"-",AC9/AD9) -> - | AF9: 0 | AG9: 0 | AH9: =IF(AG9=0,"-",AF9/AG9) -> - | AI9: 0 | AJ9: 0 | AK9: =IF(AJ9=0,"-",AI9/AJ9) -> - | AL9: 6 | AM9: 1 | AN9: =IF(AM9=0,"",AL9/AM9) -> 6 | AO9: 0 | AP9: 0 | AQ9: =IF(AP9=0,"-",AO9/AP9) -> - | AR9: 0 | AS9: 0 | AT9: =IF(AS9=0,"-",AR9/AS9) -> - | AU9: 8 | AV9: 1 | AW9: =IF(AV9=0,"",AU9/AV9) -> 8 | AX9: 0 | AY9: 0 | AZ9: =IF(AY9=0,"-",AX9/AY9) -> - | BA9: 0 | BB9: 0 | BC9: =IF(BB9=0,"-",BA9/BB9) -> - | BD9: 0 | BE9: 0 | BF9: =IF(BE9=0,"-",BD9/BE9) -> - | BG9: 0 | BH9: 0 | BI9: =IF(BH9=0,"-",BG9/BH9) -> - | BJ9: 0 | BK9: 0 | BL9: =IF(BK9=0,"-",BJ9/BK9) -> - | BM9: =BJ9+BG9+BD9+BA9+AX9+AU9+AR9+AO9+AL9+K9+Q9+N9+H9+E9+AI9+AF9+AC9+Z9+W9+B9 -> 428 | BN9: =BK9+BH9+BE9+BB9+AY9+AV9+AS9+AP9+AM9+L9+R9+O9+I9+F9+AJ9+AG9+AD9+AA9+X9+C9 -> 57 | BO9: =IF(BN9=0,"",BM9/BN9) -> 7.5087719
A10: 45236 | B10: 13 | C10: 2 | D10: =IF(C10=0,"",B10/C10) -> 6.5 | E10: 8 | F10: 1 | G10: =IF(F10=0,"",E10/F10) -> 8 | H10: 9 | I10: 1 | J10: =IF(I10=0,"",H10/I10) -> 9 | K10: 0 | L10: 0 | M10: =IF(L10=0,"-",K10/L10) -> - | N10: 28 | O10: 5 | P10: =IF(O10=0,"",N10/O10) -> 5.6 | Q10: 504 | R10: 71 | S10: =IF(R10=0,"",Q10/R10) -> 7.0985915 | T10: 0 | U10: 0 | V10: =IF(U10=0,"-",T10/U10) -> - | W10: 7 | X10: 1 | Y10: =IF(X10=0,"-",W10/X10) -> 7 | Z10: 0 | AA10: 0 | AB10: =IF(AA10=0,"-",Z10/AA10) -> - | AC10: 0 | AD10: 0 | AE10: =IF(AD10=0,"-",AC10/AD10) -> - | AF10: 0 | AG10: 0 | AH10: =IF(AG10=0,"-",AF10/AG10) -> - | AI10: 5 | AJ10: 1 | AK10: =IF(AJ10=0,"-",AI10/AJ10) -> 5 | AL10: 12 | AM10: 2 | AN10: =IF(AM10=0,"",AL10/AM10) -> 6 | AO10: 0 | AP10: 0 | AQ10: =IF(AP10=0,"-",AO10/AP10) -> - | AR10: 0 | AS10: 0 | AT10: =IF(AS10=0,"-",AR10/AS10) -> - | AU10: 0 | AV10: 0 | AW10: =IF(AV10=0,"-",AU10/AV10) -> - | AX10: 0 | AY10: 0 | AZ10: =IF(AY10=0,"-",AX10/AY10) -> - | BA10: 0 | BB10: 0 | BC10: =IF(BB10=0,"-",BA10/BB10) -> - | BD10: 0 | BE10: 0 | BF10: =IF(BE10=0,"-",BD10/BE10) -> - | BG10: 0 | BH10: 0 | BI10: =IF(BH10=0,"-",BG10/BH10) -> - | BJ10: 0 | BK10: 0 | BL10: =IF(BK10=0,"-",BJ10/BK10) -> - | BM10: =BJ10+BG10+BD10+BA10+AX10+AU10+AR10+AO10+AL10+K10+Q10+N10+H10+E10+AI10+AF10+AC10+Z10+W10+B10 -> 586 | BN10: =BK10+BH10+BE10+BB10+AY10+AV10+AS10+AP10+AM10+L10+R10+O10+I10+F10+AJ10+AG10+AD10+AA10+X10+C10 -> 84 | BO10: =IF(BN10=0,"",BM10/BN10) -> 6.9761905
A11: 45237 | B11: 31 | C11: 4 | D11: =IF(C11=0,"",B11/C11) -> 7.75 | E11: 0 | F11: 0 | G11: =IF(F11=0,"-",E11/F11) -> - | H11: 15 | I11: 2 | J11: =IF(I11=0,"",H11/I11) -> 7.5 | K11: 1 | L11: 1 | M11: =IF(L11=0,"",K11/L11) -> 1 | N11: 26 | O11: 6 | P11: =IF(O11=0,"",N11/O11) -> 4.3333333 | Q11: 407 | R11: 61 | S11: =IF(R11=0,"",Q11/R11) -> 6.6721311 | T11: 0 | U11: 0 | V11: =IF(U11=0,"-",T11/U11) -> - | W11: 0 | X11: 0 | Y11: =IF(X11=0,"-",W11/X11) -> - | Z11: 0 | AA11: 0 | AB11: =IF(AA11=0,"-",Z11/AA11) -> - | AC11: 0 | AD11: 0 | AE11: =IF(AD11=0,"-",AC11/AD11) -> - | AF11: 0 | AG11: 0 | AH11: =IF(AG11=0,"-",AF11/AG11) -> - | AI11: 0 | AJ11: 0 | AK11: =IF(AJ11=0,"-",AI11/AJ11) -> - | AL11: 14 | AM11: 2 | AN11: =IF(AM11=0,"",AL11/AM11) -> 7 | AO11: 0 | AP11: 0 | AQ11: =IF(AP11=0,"-",AO11/AP11) -> - | AR11: 0 | AS11: 0 | AT11: =IF(AS11=0,"-",AR11/AS11) -> - | AU11: 0 | AV11: 0 | AW11: =IF(AV11=0,"-",AU11/AV11) -> - | AX11: 0 | AY11: 0 | AZ11: =IF(AY11=0,"-",AX11/AY11) -> - | BA11: 9 | BB11: 1 | BC11: =IF(BB11=0,"",BA11/BB11) -> 9 | BD11: 0 | BE11: 0 | BF11: =IF(BE11=0,"-",BD11/BE11) -> - | BG11: 0 | BH11: 0 | BI11: =IF(BH11=0,"-",BG11/BH11) -> - | BJ11: 0 | BK11: 0 | BL11: =IF(BK11=0,"-",BJ11/BK11) -> - | BM11: =BJ11+BG11+BD11+BA11+AX11+AU11+AR11+AO11+AL11+K11+Q11+N11+H11+E11+AI11+AF11+AC11+Z11+W11+B11 -> 503 | BN11: =BK11+BH11+BE11+BB11+AY11+AV11+AS11+AP11+AM11+L11+R11+O11+I11+F11+AJ11+AG11+AD11+AA11+X11+C11 -> 77 | BO11: =IF(BN11=0,"",BM11/BN11) -> 6.5324675
A12: 45238 | B12: 39 | C12: 5 | D12: =IF(C12=0,"",B12/C12) -> 7.8 | E12: 8 | F12: 1 | G12: =IF(F12=0,"",E12/F12) -> 8 | H12: 0 | I12: 0 | J12: =IF(I12=0,"-",H12/I12) -> - | K12: 1 | L12: 1 | M12: =IF(L12=0,"",K12/L12) -> 1 | N12: 39 | O12: 7 | P12: =IF(O12=0,"",N12/O12) -> 5.5714286 | Q12: 440 | R12: 62 | S12: =IF(R12=0,"",Q12/R12) -> 7.0967742 | T12: 0 | U12: 0 | V12: =IF(U12=0,"-",T12/U12) -> - | W12: 0 | X12: 0 | Y12: =IF(X12=0,"-",W12/X12) -> - | Z12: 2 | AA12: 1 | AB12: =IF(AA12=0,"",Z12/AA12) -> 2 | AC12: 5 | AD12: 2 | AE12: =IF(AD12=0,"-",AC12/AD12) -> 2.5 | AF12: 0 | AG12: 0 | AH12: =IF(AG12=0,"-",AF12/AG12) -> - | AI12: 0 | AJ12: 0 | AK12: =IF(AJ12=0,"-",AI12/AJ12) -> - | AL12: 0 | AM12: 0 | AN12: =IF(AM12=0,"-",AL12/AM12) -> - | AO12: 0 | AP12: 0 | AQ12: =IF(AP12=0,"-",AO12/AP12) -> - | AR12: 0 | AS12: 0 | AT12: =IF(AS12=0,"-",AR12/AS12) -> - | AU12: 6 | AV12: 1 | AW12: =IF(AV12=0,"",AU12/AV12) -> 6 | AX12: 0 | AY12: 0 | AZ12: =IF(AY12=0,"-",AX12/AY12) -> - | BA12: 149 | BB12: 22 | BC12: =IF(BB12=0,"",BA12/BB12) -> 6.7727273 | BD12: 0 | BE12: 0 | BF12: =IF(BE12=0,"-",BD12/BE12) -> - | BG12: 0 | BH12: 0 | BI12: =IF(BH12=0,"-",BG12/BH12) -> - | BJ12: 0 | BK12: 0 | BL12: =IF(BK12=0,"-",BJ12/BK12) -> - | BM12: =BJ12+BG12+BD12+BA12+AX12+AU12+AR12+AO12+AL12+K12+Q12+N12+H12+E12+AI12+AF12+AC12+Z12+W12+B12 -> 689 | BN12: =BK12+BH12+BE12+BB12+AY12+AV12+AS12+AP12+AM12+L12+R12+O12+I12+F12+AJ12+AG12+AD12+AA12+X12+C12 -> 102 | BO12: =IF(BN12=0,"",BM12/BN12) -> 6.754902
A13: 45239 | B13: 37 | C13: 6 | D13: =IF(C13=0,"",B13/C13) -> 6.1666667 | E13: 8 | F13: 1 | G13: =IF(F13=0,"",E13/F13) -> 8 | H13: 9 | I13: 1 | J13: =IF(I13=0,"",H13/I13) -> 9 | K13: 0 | L13: 0 | M13: =IF(L13=0,"-",K13/L13) -> - | N13: 39 | O13: 7 | P13: =IF(O13=0,"",N13/O13) -> 5.5714286 | Q13: 319 | R13: 41 | S13: =IF(R13=0,"",Q13/R13) -> 7.7804878 | T13: 0 | U13: 0 | V13: =IF(U13=0,"-",T13/U13) -> - | W13: 9 | X13: 1 | Y13: =IF(X13=0,"-",W13/X13) -> 9 | Z13: 0 | AA13: 0 | AB13: =IF(AA13=0,"-",Z13/AA13) -> - | AC13: 4 | AD13: 1 | AE13: =IF(AD13=0,"-",AC13/AD13) -> 4 | AF13: 0 | AG13: 0 | AH13: =IF(AG13=0,"-",AF13/AG13) -> - | AI13: 6 | AJ13: 1 | AK13: =IF(AJ13=0,"-",AI13/AJ13) -> 6 | AL13: 7 | AM13: 1 | AN13: =IF(AM13=0,"",AL13/AM13) -> 7 | AO13: 0 | AP13: 0 | AQ13: =IF(AP13=0,"-",AO13/AP13) -> - | AR13: 0 | AS13: 0 | AT13: =IF(AS13=0,"-",AR13/AS13) -> - | AU13: 0 | AV13: 0 | AW13: =IF(AV13=0,"-",AU13/AV13) -> - | AX13: 6 | AY13: 1 | AZ13: =IF(AY13=0,"-",AX13/AY13) -> 6 | BA13: 0 | BB13: 0 | BC13: =IF(BB13=0,"-",BA13/BB13) -> - | BD13: 0 | BE13: 0 | BF13: =IF(BE13=0,"-",BD13/BE13) -> - | BG13: 0 | BH13: 0 | BI13: =IF(BH13=0,"-",BG13/BH13) -> - | BJ13: 0 | BK13: 0 | BL13: =IF(BK13=0,"-",BJ13/BK13) -> - | BM13: =BJ13+BG13+BD13+BA13+AX13+AU13+AR13+AO13+AL13+K13+Q13+N13+H13+E13+AI13+AF13+AC13+Z13+W13+B13 -> 444 | BN13: =BK13+BH13+BE13+BB13+AY13+AV13+AS13+AP13+AM13+L13+R13+O13+I13+F13+AJ13+AG13+AD13+AA13+X13+C13 -> 61 | BO13: =IF(BN13=0,"",BM13/BN13) -> 7.2786885
A14: 45240 | B14: 34 | C14: 4 | D14: =IF(C14=0,"",B14/C14) -> 8.5 | E14: 8 | F14: 1 | G14: =IF(F14=0,"",E14/F14) -> 8 | H14: 27 | I14: 3 | J14: =IF(I14=0,"",H14/I14) -> 9 | K14: 0 | L14: 0 | M14: =IF(L14=0,"-",K14/L14) -> - | N14: 35 | O14: 6 | P14: =IF(O14=0,"",N14/O14) -> 5.8333333 | Q14: 407 | R14: 56 | S14: =IF(R14=0,"",Q14/R14) -> 7.2678571 | T14: 0 | U14: 0 | V14: =IF(U14=0,"-",T14/U14) -> - | W14: 0 | X14: 0 | Y14: =IF(X14=0,"-",W14/X14) -> - | Z14: 0 | AA14: 0 | AB14: =IF(AA14=0,"-",Z14/AA14) -> - | AC14: 0 | AD14: 0 | AE14: =IF(AD14=0,"-",AC14/AD14) -> - | AF14: 0 | AG14: 0 | AH14: =IF(AG14=0,"-",AF14/AG14) -> - | AI14: 0 | AJ14: 0 | AK14: =IF(AJ14=0,"-",AI14/AJ14) -> - | AL14: 0 | AM14: 0 | AN14: =IF(AM14=0,"",AL14/AM14) | AO14: 0 | AP14: 0 | AQ14: =IF(AP14=0,"-",AO14/AP14) -> - | AR14: 14 | AS14: 2 | AT14: =IF(AS14=0,"",AR14/AS14) -> 7 | AU14: 0 | AV14: 0 | AW14: =IF(AV14=0,"-",AU14/AV14) -> - | AX14: 14 | AY14: 2 | AZ14: =IF(AY14=0,"-",AX14/AY14) -> 7 | BA14: 96 | BB14: 14 | BC14: =IF(BB14=0,"",BA14/BB14) -> 6.8571429 | BD14: 0 | BE14: 0 | BF14: =IF(BE14=0,"-",BD14/BE14) -> - | BG14: 0 | BH14: 0 | BI14: =IF(BH14=0,"-",BG14/BH14) -> - | BJ14: 0 | BK14: 0 | BL14: =IF(BK14=0,"-",BJ14/BK14) -> - | BM14: =BJ14+BG14+BD14+BA14+AX14+AU14+AR14+AO14+AL14+K14+Q14+N14+H14+E14+AI14+AF14+AC14+Z14+W14+B14 -> 635 | BN14: =BK14+BH14+BE14+BB14+AY14+AV14+AS14+AP14+AM14+L14+R14+O14+I14+F14+AJ14+AG14+AD14+AA14+X14+C14 -> 88 | BO14: =IF(BN14=0,"",BM14/BN14) -> 7.2159091
A15: 45241 | B15: 110 | C15: 13 | D15: =IF(C15=0,"-",B15/C15) -> 8.4615385 | E15: 8 | F15: 1 | G15: =IF(F15=0,"",E15/F15) -> 8 | H15: 0 | I15: 0 | J15: =IF(I15=0,"-",H15/I15) -> - | K15: 0 | L15: 0 | M15: =IF(L15=0,"-",K15/L15) -> - | N15: 21 | O15: 5 | P15: =IF(O15=0,"",N15/O15) -> 4.2 | Q15: 0 | R15: 0 | S15: =IF(R15=0,"-",Q15/R15) -> - | T15: 0 | U15: 0 | V15: =IF(U15=0,"-",T15/U15) -> - | W15: 6 | X15: 3 | Y15: =IF(X15=0,"-",W15/X15) -> 2 | Z15: 0 | AA15: 0 | AB15: =IF(AA15=0,"-",Z15/AA15) -> - | AC15: 0 | AD15: 0 | AE15: =IF(AD15=0,"-",AC15/AD15) -> - | AF15: 5 | AG15: 1 | AH15: =IF(AG15=0,"-",AF15/AG15) -> 5 | AI15: 0 | AJ15: 0 | AK15: =IF(AJ15=0,"-",AI15/AJ15) -> - | AL15: 12 | AM15: 2 | AN15: =IF(AM15=0,"",AL15/AM15) -> 6 | AO15: 13 | AP15: 2 | AQ15: =IF(AP15=0,"",AO15/AP15) -> 6.5 | AR15: 21 | AS15: 3 | AT15: =IF(AS15=0,"",AR15/AS15) -> 7 | AU15: 0 | AV15: 0 | AW15: =IF(AV15=0,"-",AU15/AV15) -> - | AX15: 0 | AY15: 0 | AZ15: =IF(AY15=0,"-",AX15/AY15) -> - | BA15: 28 | BB15: 4 | BC15: =IF(BB15=0,"",BA15/BB15) -> 7 | BD15: 0 | BE15: 0 | BF15: =IF(BE15=0,"-",BD15/BE15) -> - | BG15: 0 | BH15: 0 | BI15: =IF(BH15=0,"-",BG15/BH15) -> - | BJ15: 0 | BK15: 0 | BL15: =IF(BK15=0,"-",BJ15/BK15) -> - | BM15: =BJ15+BG15+BD15+BA15+AX15+AU15+AR15+AO15+AL15+K15+Q15+N15+H15+E15+AI15+AF15+AC15+Z15+W15+B15 -> 224 | BN15: =BK15+BH15+BE15+BB15+AY15+AV15+AS15+AP15+AM15+L15+R15+O15+I15+F15+AJ15+AG15+AD15+AA15+X15+C15 -> 34 | BO15: =IF(BN15=0,"",BM15/BN15) -> 6.5882353
A16: 45242 | B16: 34 | C16: 4 | D16: =IF(C16=0,"",B16/C16) -> 8.5 | E16: 0 | F16: 0 | G16: =IF(F16=0,"-",E16/F16) -> - | H16: 0 | I16: 0 | J16: =IF(I16=0,"-",H16/I16) -> - | K16: 0 | L16: 0 | M16: =IF(L16=0,"-",K16/L16) -> - | N16: 11 | O16: 2 | P16: =IF(O16=0,"",N16/O16) -> 5.5 | Q16: 0 | R16: 0 | S16: =IF(R16=0,"-",Q16/R16) -> - | T16: 0 | U16: 0 | V16: =IF(U16=0,"-",T16/U16) -> - | W16: 0 | X16: 0 | Y16: =IF(X16=0,"-",W16/X16) -> - | Z16: 0 | AA16: 0 | AB16: =IF(AA16=0,"-",Z16/AA16) -> - | AC16: 0 | AD16: 0 | AE16: =IF(AD16=0,"-",AC16/AD16) -> - | AF16: 0 | AG16: 0 | AH16: =IF(AG16=0,"-",AF16/AG16) -> - | AI16: 0 | AJ16: 0 | AK16: =IF(AJ16=0,"-",AI16/AJ16) -> - | AL16: 14 | AM16: 2 | AN16: =IF(AM16=0,"-",AL16/AM16) -> 7 | AO16: 0 | AP16: 0 | AQ16: =IF(AP16=0,"-",AO16/AP16) -> - | AR16: 22 | AS16: 3 | AT16: =IF(AS16=0,"-",AR16/AS16) -> 7.3333333 | AU16: 0 | AV16: 0 | AW16: =IF(AV16=0,"-",AU16/AV16) -> - | AX16: 0 | AY16: 0 | AZ16: =IF(AY16=0,"-",AX16/AY16) -> - | BA16: 16 | BB16: 2 | BC16: =IF(BB16=0,"",BA16/BB16) -> 8 | BD16: 0 | BE16: 0 | BF16: =IF(BE16=0,"-",BD16/BE16) -> - | BG16: 0 | BH16: 0 | BI16: =IF(BH16=0,"-",BG16/BH16) -> - | BJ16: 0 | BK16: 0 | BL16: =IF(BK16=0,"-",BJ16/BK16) -> - | BM16: =BJ16+BG16+BD16+BA16+AX16+AU16+AR16+AO16+AL16+K16+Q16+N16+H16+E16+AI16+AF16+AC16+Z16+W16+B16 -> 97 | BN16: =BK16+BH16+BE16+BB16+AY16+AV16+AS16+AP16+AM16+L16+R16+O16+I16+F16+AJ16+AG16+AD16+AA16+X16+C16 -> 13 | BO16: =IF(BN16=0,"",BM16/BN16) -> 7.4615385
A17: 45243 | B17: 8 | C17: 1 | D17: =IF(C17=0,"",B17/C17) -> 8 | E17: 0 | F17: 0 | G17: =IF(F17=0,"-",E17/F17) -> - | H17: 0 | I17: 0 | J17: =IF(I17=0,"-",H17/I17) -> - | K17: 0 | L17: 0 | M17: =IF(L17=0,"-",K17/L17) -> - | N17: 34 | O17: 7 | P17: =IF(O17=0,"",N17/O17) -> 4.8571429 | Q17: 251 | R17: 41 | S17: =IF(R17=0,"",Q17/R17) -> 6.1219512 | T17: 0 | U17: 0 | V17: =IF(U17=0,"-",T17/U17) -> - | W17: 2 | X17: 1 | Y17: =IF(X17=0,"-",W17/X17) -> 2 | Z17: 0 | AA17: 0 | AB17: =IF(AA17=0,"-",Z17/AA17) -> - | AC17: 1 | AD17: 1 | AE17: =IF(AD17=0,"-",AC17/AD17) -> 1 | AF17: 0 | AG17: 0 | AH17: =IF(AG17=0,"-",AF17/AG17) -> - | AI17: 8 | AJ17: 2 | AK17: =IF(AJ17=0,"-",AI17/AJ17) -> 4 | AL17: 15 | AM17: 2 | AN17: =IF(AM17=0,"",AL17/AM17) -> 7.5 | AO17: 0 | AP17: 0 | AQ17: =IF(AP17=0,"-",AO17/AP17) -> - | AR17: 0 | AS17: 0 | AT17: =IF(AS17=0,"-",AR17/AS17) -> - | AU17: 0 | AV17: 0 | AW17: =IF(AV17=0,"-",AU17/AV17) -> - | AX17: 0 | AY17: 0 | AZ17: =IF(AY17=0,"-",AX17/AY17) -> - | BA17: 24 | BB17: 3 | BC17: =IF(BB17=0,"",BA17/BB17) -> 8 | BD17: 0 | BE17: 0 | BF17: =IF(BE17=0,"-",BD17/BE17) -> - | BG17: 0 | BH17: 0 | BI17: =IF(BH17=0,"-",BG17/BH17) -> - | BJ17: 0 | BK17: 0 | BL17: =IF(BK17=0,"-",BJ17/BK17) -> - | BM17: =BJ17+BG17+BD17+BA17+AX17+AU17+AR17+AO17+AL17+K17+Q17+N17+H17+E17+AI17+AF17+AC17+Z17+W17+B17 -> 343 | BN17: =BK17+BH17+BE17+BB17+AY17+AV17+AS17+AP17+AM17+L17+R17+O17+I17+F17+AJ17+AG17+AD17+AA17+X17+C17 -> 58 | BO17: =IF(BN17=0,"",BM17/BN17) -> 5.9137931
A18: 45244 | B18: 53 | C18: 6 | D18: =IF(C18=0,"",B18/C18) -> 8.8333333 | E18: 0 | F18: 0 | G18: =IF(F18=0,"-",E18/F18) -> - | H18: 0 | I18: 0 | J18: =IF(I18=0,"-",H18/I18) -> - | K18: 0 | L18: 0 | M18: =IF(L18=0,"-",K18/L18) -> - | N18: 38 | O18: 5 | P18: =IF(O18=0,"",N18/O18) -> 7.6 | Q18: 4 | R18: 1 | S18: =IF(R18=0,"",Q18/R18) -> 4 | T18: 6 | U18: 1 | V18: =IF(U18=0,"-",T18/U18) -> 6 | W18: 1 | X18: 1 | Y18: =IF(X18=0,"-",W18/X18) -> 1 | Z18: 0 | AA18: 0 | AB18: =IF(AA18=0,"-",Z18/AA18) -> - | AC18: 0 | AD18: 0 | AE18: =IF(AD18=0,"-",AC18/AD18) -> - | AF18: 0 | AG18: 0 | AH18: =IF(AG18=0,"-",AF18/AG18) -> - | AI18: 2 | AJ18: 1 | AK18: =IF(AJ18=0,"-",AI18/AJ18) -> 2 | AL18: 58 | AM18: 7 | AN18: =IF(AM18=0,"",AL18/AM18) -> 8.2857143 | AO18: 0 | AP18: 0 | AQ18: =IF(AP18=0,"-",AO18/AP18) -> - | AR18: 0 | AS18: 0 | AT18: =IF(AS18=0,"-",AR18/AS18) -> - | AU18: 0 | AV18: 0 | AW18: =IF(AV18=0,"-",AU18/AV18) -> - | AX18: 0 | AY18: 0 | AZ18: =IF(AY18=0,"-",AX18/AY18) -> - | BA18: 94 | BB18: 14 | BC18: =IF(BB18=0,"-",BA18/BB18) -> 6.7142857 | BD18: 0 | BE18: 0 | BF18: =IF(BE18=0,"-",BD18/BE18) -> - | BG18: 0 | BH18: 0 | BI18: =IF(BH18=0,"-",BG18/BH18) -> - | BJ18: 0 | BK18: 0 | BL18: =IF(BK18=0,"-",BJ18/BK18) -> - | BM18: =BJ18+BG18+BD18+BA18+AX18+AU18+AR18+AO18+AL18+K18+Q18+N18+H18+E18+AI18+AF18+AC18+Z18+W18+B18 -> 250 | BN18: =BK18+BH18+BE18+BB18+AY18+AV18+AS18+AP18+AM18+L18+R18+O18+I18+F18+AJ18+AG18+AD18+AA18+X18+C18 -> 35 | BO18: =IF(BN18=0,"",BM18/BN18) -> 7.1428571
